<?xml version="1.0"?>
<robot name="kuka_kr6r900sixx" xmlns:xacro="http://wiki.ros.org/xacro">
  <xacro:include filename="$(find kuka_kr6_support)/urdf/kr6r900sixx_macro.xacro" />
  <xacro:kuka_kr6r900sixx prefix=""/>

  <xacro:include filename="$(find kuka_resources)/urdf/common_constants.xacro"/>
  <xacro:include filename="$(find kuka_resources)/urdf/common_materials.xacro"/>

  <!-- <xacro:macro name="kuka_kr6r900sixx" params="prefix"> -->
    <link name="base_link">
      <visual>
        <origin xyz="0 0 0" rpy="0 0 0"/>
        <geometry>
          <mesh filename="package://kuka_kr6_support/meshes/kr6_agilus/visual/base_link.dae" />
        </geometry>
        <xacro:material_kuka_pedestal />
      </visual>
      <collision>
        <origin xyz="0 0 0" rpy="0 0 0"/>
        <geometry>
          <mesh filename="package://kuka_kr6_support/meshes/kr6_agilus/collision/base_link.stl" />
        </geometry>
      </collision>
    </link>
    <link name="link_1">
      <visual>
        <origin xyz="0 0 0" rpy="0 0 0"/>
        <geometry>
          <mesh filename="package://kuka_kr6_support/meshes/kr6_agilus/visual/link_1.dae" />
        </geometry>
        <xacro:material_kuka_orange />
      </visual>
      <collision>
        <origin xyz="0 0 0" rpy="0 0 0"/>
        <geometry>
          <mesh filename="package://kuka_kr6_support/meshes/kr6_agilus/collision/link_1.stl" />
        </geometry>
      </collision>
    </link>
    <link name="link_2">
      <visual>
        <origin xyz="0 0 0" rpy="0 0 0"/>
        <geometry>
          <mesh filename="package://kuka_kr6_support/meshes/kr6r900sixx/visual/link_2.dae"/>
        </geometry>
        <xacro:material_kuka_orange />
      </visual>
      <collision>
        <origin xyz="0 0 0" rpy="0 0 0"/>
        <geometry>
          <mesh filename="package://kuka_kr6_support/meshes/kr6r900sixx/collision/link_2.stl" />
        </geometry>
      </collision>
    </link>
    <link name="link_3">
      <visual>
        <origin xyz="0 0 0" rpy="0 0 0"/>
        <geometry>
          <mesh filename="package://kuka_kr6_support/meshes/kr6_agilus/visual/link_3.dae" />
        </geometry>
        <xacro:material_kuka_orange />
      </visual>
      <collision>
        <origin xyz="0 0 0" rpy="0 0 0"/>
        <geometry>
          <mesh filename="package://kuka_kr6_support/meshes/kr6_agilus/collision/link_3.stl" />
        </geometry>
      </collision>
    </link>
    <link name="link_4">
      <visual>
        <origin xyz="0 0 0" rpy="0 0 0"/>
        <geometry>
          <mesh filename="package://kuka_kr6_support/meshes/kr6r900sixx/visual/link_4.dae" />
        </geometry>
        <xacro:material_kuka_orange />
      </visual>
      <collision>
        <origin xyz="0 0 0" rpy="0 0 0"/>
        <geometry>
          <mesh filename="package://kuka_kr6_support/meshes/kr6r900sixx/collision/link_4.stl" />
        </geometry>
      </collision>
    </link>
    <link name="link_5">
      <visual>
        <origin xyz="0 0 0" rpy="0 0 0"/>
        <geometry>
          <mesh filename="package://kuka_kr6_support/meshes/kr6_agilus/visual/link_5.dae" />
        </geometry>
        <xacro:material_kuka_orange />
      </visual>
      <collision>
        <origin xyz="0 0 0" rpy="0 0 0"/>
        <geometry>
          <mesh filename="package://kuka_kr6_support/meshes/kr6_agilus/collision/link_5.stl" />
        </geometry>
      </collision>
    </link>
    <link name="link_6">
      <visual>
        <origin xyz="0 0 0" rpy="0 0 0"/>
        <geometry>
          <mesh filename="package://kuka_kr6_support/meshes/kr6_agilus/visual/link_6.dae" />
        </geometry>
        <xacro:material_kuka_pedestal />
      </visual>
      <collision>
        <origin xyz="0 0 0" rpy="0 0 0"/>
        <geometry>
          <mesh filename="package://kuka_kr6_support/meshes/kr6_agilus/collision/link_6.stl" />
        </geometry>
      </collision>
    </link>
    <!-- Following REP199, this frame shall be use to attach EEF or other equipment -->
    <link name="flange" />

    <joint name="joint_a1" type="revolute">
      <origin xyz="0 0 0.400" rpy="0 0 0"/>
      <parent link="base_link"/>
      <child link="link_1"/>
      <axis xyz="0 0 -1"/>
      <limit effort="0" lower="-2.96705972839" upper="2.96705972839" velocity="6.28318530718"/>
    </joint>
    <joint name="joint_a2" type="revolute">
      <origin xyz="0.025 0 0" rpy="0 0 0"/>
      <parent link="link_1"/>
      <child link="link_2"/>
      <axis xyz="0 1 0"/>
      <limit effort="0" lower="3.31612557879" upper="0.78539816339" velocity="5.23598775598"/>
    </joint>
    <joint name="joint_a3" type="revolute">
      <origin xyz="0.455 0 0" rpy="0 0 0"/>
      <parent link="link_2"/>
      <child link="link_3"/>
      <axis xyz="0 1 0"/>
      <limit effort="0" lower="-2.09439510239" upper="2.72271363311" velocity="6.28318530718"/>
    </joint>
    <joint name="joint_a4" type="revolute">
      <origin xyz="0 0 0.035" rpy="0 0 0"/>
      <parent link="link_3"/>
      <child link="link_4"/>
      <axis xyz="-1 0 0"/>
      <limit effort="0" lower="-3.22885911619" upper="3.22885911619" velocity="6.6497044501"/>
    </joint>
    <joint name="joint_a5" type="revolute">
      <origin xyz="0.420 0 0" rpy="0 0 0"/>
      <parent link="link_4"/>
      <child link="link_5"/>
      <axis xyz="0 1 0"/>
      <limit effort="0" lower="-2.09439510239" upper="2.09439510239" velocity="6.77187749774"/>
    </joint>
    <joint name="joint_a6" type="revolute">
      <origin xyz="0.080 0 0" rpy="0 0 0"/>
      <parent link="link_5"/>
      <child link="link_6"/>
      <axis xyz="-1 0 0"/>
      <limit effort="0" lower="-6.10865238198" upper="6.10865238198" velocity="10.7337748998"/>
    </joint>
    <joint name="joint_a6-flange" type="fixed">
      <parent link="link_6"/>
      <child link="flange"/>
      <origin xyz="0 0 0" rpy="0 0 0"/>
    </joint>

    <!-- ROS base_link to KUKA $ROBROOT coordinate system transform -->
    <link name="base" />
    <joint name="base_link-base" type="fixed">
      <origin xyz="0 0 0" rpy="0 0 0"/>
      <parent link="base_link"/>
      <child link="base"/>
    </joint>

    <!-- This frame corresponds to the $TOOL coordinate system in KUKA KRC controllers -->
    <link name="tool0" />
    <joint name="flange-tool0" type="fixed">
      <parent link="flange"/>
      <child link="tool0"/>
      <origin xyz="0 0 0" rpy="0 1.5707963268 0"/>
    </joint>
  <!-- </xacro:macro> -->
</robot>

