<?xml version="1.0" ?>
<!-- =================================================================================== -->
<!-- |    This document was autogenerated by xacro from /home/iclab/work/src/robot_models/timda/single_arm_description/urdf/single_arm_cam.urdf.xacro | -->
<!-- |    EDITING THIS FILE BY HAND IS NOT RECOMMENDED                                 | -->
<!-- =================================================================================== -->
<robot name="single_arm">
    <material name="black">
        <color rgba="0.0 0.0 0.0 1.0" />
    </material>
    <material name="blue">
        <color rgba="0.0 0.0 0.8 1.0" />
    </material>
    <material name="green">
        <color rgba="0.0 0.8 0.0 1.0" />
    </material>
    <material name="grey">
        <color rgba="0.2 0.2 0.2 1.0" />
    </material>
    <material name="orange">
        <color rgba="1.0 0.4235294117647059 0.0392156862745098 1.0" />
    </material>
    <material name="brown">
        <color rgba="0.8705882352941177 0.8117647058823529 0.7647058823529411 1.0" />
    </material>
    <material name="red">
        <color rgba="0.8 0.0 0.0 1.0" />
    </material>
    <material name="white">
        <color rgba="1.0 1.0 1.0 1.0" />
    </material>
    <!-- Constants for robot dimensions -->
    <link name="world" />
    <!-- <xacro:single_arm parent="world" side="" child="" toolrot="-1.57">
    <origin xyz="0 0 0.1" rpy="0 0 0" />
  </xacro:single_arm> -->
    <!-- <link name="r_tool_link"/> -->
    <link name="tool_link">
        <visual>
            <origin rpy="0 0 0" xyz="0 0 0" />
            <geometry>
                <box size="0.001 0.001 0.001" />
            </geometry>
        </visual>
    </link>
    <joint name="fixed" type="fixed">
        <origin rpy="0 0 0" xyz="0 0 0.1" />
        <parent link="world" />
        <child link="base" />
    </joint>
    <link name="base">
        <inertial>
            <origin rpy="0 0 0" xyz="0.000156250860732315 0.000202963757501797 -0.0546720420122521" />
            <mass value="0.323603974032196" />
            <inertia ixx="0.1" ixy="0.0" ixz="0.0" iyy="0.1" iyz="0.0" izz="0.1" />
        </inertial>
        <visual>
            <origin rpy="0 0 0" xyz="0 0 0" />
            <geometry>
                <mesh filename="package://single_arm_description/meshes/base.STL" />
            </geometry>
            <material name="grey">
                <!-- <color 
					rgba="0.792156862745098 0.819607843137255 0.933333333333333 1" /> -->
            </material>
        </visual>
        <collision>
            <origin rpy="0 0 0" xyz="0 0 0" />
            <geometry>
                <mesh filename="package://single_arm_description/meshes/base.STL" />
            </geometry>
        </collision>
    </link>
    <joint name="joint_1" type="revolute">
        <origin rpy="-1.5707963267949 -2.60398896659329E-32 1.5707963267949" xyz="0 0 0.0550000000000002" />
        <parent link="base" />
        <child link="link_1" />
        <axis xyz="0 -1 0" />
        <limit effort="1000" lower="-3.14" upper="3.14" velocity="6.5" />
        <dynamics damping="0.7" />
    </joint>
    <link name="link_1">
        <inertial>
            <origin rpy="0 0 0" xyz="-3.64540734812575E-06 0.00119778550610652 -0.000421399675048756" />
            <mass value="0.386131223153925" />
            <inertia ixx="0.1" ixy="0.0" ixz="0.0" iyy="0.1" iyz="0.0" izz="0.1" />
        </inertial>
        <visual>
            <origin rpy="0 0 0" xyz="0 0 0" />
            <geometry>
                <mesh filename="package://single_arm_description/meshes/link_1.STL" />
            </geometry>
            <material name="grey">
                <!-- <color
		  		rgba="0.898039215686275 0.917647058823529 0.929411764705882 1" /> -->
            </material>
        </visual>
        <collision>
            <origin rpy="0 0 0" xyz="0 0 0" />
            <geometry>
                <mesh filename="package://single_arm_description/meshes/link_1.STL" />
            </geometry>
        </collision>
    </link>
    <joint name="joint_2" type="revolute">
        <origin rpy="-1.5707963267949 7.39557098644699E-32 -1.5707963267949" xyz="0 0 0" />
        <parent link="link_1" />
        <child link="link_2" />
        <axis xyz="0 -1 0" />
        <limit effort="1000" lower="-3.14" upper="3.14" velocity="6.5" />
        <dynamics damping="0.7" />
    </joint>
    <link name="link_2">
        <inertial>
            <origin rpy="0 0 0" xyz="0.000683310419598862 -8.00535195483731E-05 0.117541995924546" />
            <mass value="0.479430893999342" />
            <inertia ixx="0.1" ixy="0.0" ixz="0.0" iyy="0.1" iyz="0.0" izz="0.1" />
        </inertial>
        <visual>
            <origin rpy="0 0 0" xyz="0 0 0" />
            <geometry>
                <mesh filename="package://single_arm_description/meshes/link_2.STL" />
            </geometry>
            <material name="grey">
                <!-- <color
		  		rgba="0.898039215686275 0.917647058823529 0.929411764705882 1" /> -->
            </material>
        </visual>
        <collision>
            <origin rpy="0 0 0" xyz="0 0 0" />
            <geometry>
                <mesh filename="package://single_arm_description/meshes/link_2.STL" />
            </geometry>
        </collision>
    </link>
    <joint name="joint_3" type="revolute">
        <origin rpy="1.5707963267949 4.63843178081015E-17 6.91111242388425E-16" xyz="0 0 0.174" />
        <parent link="link_2" />
        <child link="link_3" />
        <axis xyz="0 1 0" />
        <limit effort="1000" lower="-3.14" upper="3.14" velocity="6.5" />
        <dynamics damping="0.7" />
    </joint>
    <link name="link_3">
        <inertial>
            <origin rpy="0 0 0" xyz="-0.0220564838621471 0.101455973505417 -8.62457453022769E-05" />
            <mass value="0.568306813792926" />
            <inertia ixx="0.1" ixy="0.0" ixz="0.0" iyy="0.1" iyz="0.0" izz="0.1" />
        </inertial>
        <visual>
            <origin rpy="0 0 0" xyz="0 0 0" />
            <geometry>
                <mesh filename="package://single_arm_description/meshes/link_3.STL" />
            </geometry>
            <material name="grey">
                <!-- <color
		  		rgba="0.898039215686275 0.917647058823529 0.929411764705882 1" /> -->
            </material>
        </visual>
        <collision>
            <origin rpy="0 0 0" xyz="0 0 0" />
            <geometry>
                <mesh filename="package://single_arm_description/meshes/link_3.STL" />
            </geometry>
        </collision>
    </link>
    <joint name="joint_4" type="revolute">
        <origin rpy="-1.5707963267949 -1.40443212615082E-14 1.75438367537121E-15" xyz="-0.0299999998727122 0.115999993001519 0.0359999999999999" />
        <parent link="link_3" />
        <child link="link_4" />
        <axis xyz="0 -1 0" />
        <limit effort="1000" lower="-3.14" upper="3.14" velocity="6.5" />
        <dynamics damping="0.7" />
    </joint>
    <link name="link_4">
        <inertial>
            <origin rpy="0 0 0" xyz="0.0297389855299131 0.0361651889050357 0.108377256276242" />
            <mass value="0.457613402476782" />
            <inertia ixx="0.1" ixy="0.0" ixz="0.0" iyy="0.1" iyz="0.0" izz="0.1" />
        </inertial>
        <visual>
            <origin rpy="0 0 0" xyz="0 0 0" />
            <geometry>
                <mesh filename="package://single_arm_description/meshes/link_4.STL" />
            </geometry>
            <material name="grey">
                <!-- <color
		  		rgba="0.898039215686275 0.917647058823529 0.929411764705882 1" /> -->
            </material>
        </visual>
        <collision>
            <origin rpy="0 0 0" xyz="0 0 0" />
            <geometry>
                <mesh filename="package://single_arm_description/meshes/link_4.STL" />
            </geometry>
        </collision>
    </link>
    <joint name="joint_5" type="revolute">
        <origin rpy="1.5707963267949 -8.80083043478898E-16 -2.49800180540655E-16" xyz="0.029999999872713 0.0359999999999987 0.162" />
        <parent link="link_4" />
        <child link="link_5" />
        <axis xyz="0 1 0" />
        <limit effort="1000" lower="-3.14" upper="3.14" velocity="6.5" />
        <dynamics damping="0.7" />
    </joint>
    <link name="link_5">
        <inertial>
            <origin rpy="0 0 0" xyz="-0.000172095429412281 0.102690028206534 -6.66794215013755E-05" />
            <mass value="0.448277275798768" />
            <inertia ixx="0.1" ixy="0.0" ixz="0.0" iyy="0.1" iyz="0.0" izz="0.1" />
        </inertial>
        <visual>
            <origin rpy="0 0 0" xyz="0 0 0" />
            <geometry>
                <mesh filename="package://single_arm_description/meshes/link_5.STL" />
            </geometry>
            <material name="grey">
                <!-- <color
		  		rgba="0.792156862745098 0.819607843137255 0.933333333333333 1" /> -->
            </material>
        </visual>
        <collision>
            <origin rpy="0 0 0" xyz="0 0 0" />
            <geometry>
                <mesh filename="package://single_arm_description/meshes/link_5.STL" />
            </geometry>
        </collision>
    </link>
    <joint name="joint_6" type="revolute">
        <origin rpy="-1.5707963267949 0 4.46815747097797E-32" xyz="0 0.108000511190835 0.0360000000000014" />
        <parent link="link_5" />
        <child link="link_6" />
        <axis xyz="0 -1 0" />
        <limit effort="1000" lower="-3.14" upper="3.14" velocity="6.5" />
        <dynamics damping="0.7" />
    </joint>
    <link name="link_6">
        <inertial>
            <origin rpy="0 0 0" xyz="1.14707347786958E-08 0.0359051244401507 0.076720238383497" />
            <mass value="0.205818407044008" />
            <inertia ixx="0.1" ixy="0.0" ixz="0.0" iyy="0.1" iyz="0.0" izz="0.1" />
        </inertial>
        <visual>
            <origin rpy="0 0 0" xyz="0 0 0" />
            <geometry>
                <mesh filename="package://single_arm_description/meshes/link_6.STL" />
            </geometry>
            <material name="grey">
                <!-- <color
		  		rgba="0.898039215686275 0.917647058823529 0.929411764705882 1" /> -->
            </material>
        </visual>
        <collision>
            <origin rpy="0 0 0" xyz="0 0 0" />
            <geometry>
                <mesh filename="package://single_arm_description/meshes/link_6.STL" />
            </geometry>
        </collision>
    </link>
    <!-- <link
	    name="${side}link_7">
	    <inertial>
	      <origin
		xyz="-0.00300603996967419 -5.54762008899146E-05 0.256296304324454"
		rpy="0 0 0" />
	      <mass
		value="0.0968605125725848" />
	      <inertia
		ixx="0.000598660550174727"
		ixy="1.6879862442818E-08"
		ixz="-2.31313376077572E-05"
		iyy="0.000605976408521062"
		iyz="1.75519608508907E-07"
		izz="2.73730335090959E-05" />
	    </inertial>
	    <visual>
	      <origin
		xyz="0 0 0"
		rpy="0 0 0" />
	      <geometry>
		<mesh
		  filename="package://single_arm_description/meshes/link_7.STL" />
	      </geometry>
	      <material
		name="">
		<color
		  rgba="1 1 1 1" />
	      </material>
	    </visual>
	    <collision>
	      <origin
		xyz="0 0 0"
		rpy="0 0 0" />
	      <geometry>
		<mesh
		  filename="package://single_arm_description/meshes/link_7.STL" />
	      </geometry>
	    </collision>
	  </link> -->
    <!-- <xacro:if value="${'link' in child}">
		<joint
			name="${side}joint_7"
			type="revolute">
			<origin
				xyz="0 0.03680 0.135"
				rpy="0 0 ${toolrot}" /> -->
    <!-- rpy="1.5708 ${toolrot} 0" /> -->
    <!-- xyz="-0.008041 0.038 0.13545" -->
    <!-- xyz="-0.0025 0.038 0.135" -->
    <!-- <parent
				link="${side}link_6" />
			<child
				link="${child}" />
			<axis 
				xyz="0 0 1" />
			<limit
				lower="-3.14"
				upper="3.14"
				effort="1000"
                velocity="6.5" />
          <dynamics damping="0.7"/>
		</joint>
    </xacro:if> -->
    <joint name="joint_7" type="revolute">
        <origin rpy="0 0 -1.57" xyz="0 0.03680 0.135" />
        <!-- rpy="1.5708 ${toolrot} 0" /> -->
        <!-- xyz="-0.008041 0.038 0.13545" -->
        <!-- xyz="-0.0025 0.038 0.135" -->
        <parent link="link_6" />
        <child link="tool_link" />
        <axis xyz="0 0 1" />
        <limit effort="1000" lower="-3.14" upper="3.14" velocity="6.5" />
        <dynamics damping="0.7" />
    </joint>
    <!--
	  <link
	    name="${side}link_8">
	    <inertial>
	      <origin
		xyz="9.57945038487507E-05 -0.00931752529150576 -0.00542544640949998"
		rpy="0 0 0" />
	      <mass
		value="0.0130047980464835" />
	      <inertia
		ixx="2.46491406196035E-06"
		ixy="2.73921418079654E-09"
		ixz="-1.30294079932031E-08"
		iyy="1.47440149396087E-06"
		iyz="6.68439506061302E-07"
		izz="2.1558209563788E-06" />
	    </inertial>
	    <visual>
	      <origin
		xyz="0 0 0"
		rpy="0 0 0" />
	      <geometry>
		<mesh
		  filename="package://single_arm_description/meshes/link_8.STL" />
	      </geometry>
	      <material
		name="">
		<color
		  rgba="0.792156862745098 0.819607843137255 0.933333333333333 1" />
	      </material>
	    </visual>
	    <collision>
	      <origin
		xyz="0 0 0"
		rpy="0 0 0" />
	      <geometry>
		<mesh
		  filename="package://single_arm_description/meshes/link_8.STL" />
	      </geometry>
	    </collision>
	  </link>
	  <joint
	    name="${side}joint_8"
	    type="revolute">
	    <origin
	      xyz="0 0 0.3985"
	      rpy="-1.5708 0 0" />
	    <parent
	      link="${side}link_7" />
	    <child
	      link="${side}link_8" />
	    <axis
	      xyz="0 0 -1" />
	    <limit
	      lower="-3.14"
	      upper="3.14"
	      effort="2"
	      velocity="2" />
	  </joint>
	-->
    <!-- <xacro:single_arm_transmission side="${side}" />
	  <xacro:single_arm_gazebo side="${side}" /> -->
    <material name="aluminum">
        <color rgba="0.5 0.5 0.5 1" />
    </material>
    <material name="plastic">
        <color rgba="0.1 0.1 0.1 1" />
    </material>
    <!-- camera body, with origin at bottom screw mount -->
    <joint name="camera_joint" type="fixed">
        <origin rpy="0 -1.5707963268 0" xyz="0 0 0" />
        <parent link="tool_link" />
        <child link="camera_bottom_screw_frame" />
    </joint>
    <link name="camera_bottom_screw_frame" />
    <joint name="camera_link_joint" type="fixed">
        <origin rpy="0 0 0" xyz="0.01085 0.009 0.021" />
        <parent link="camera_bottom_screw_frame" />
        <child link="camera_link" />
    </joint>
    <link name="camera_link">
        <visual>
            <!-- the mesh origin is at front plate in between the two infrared camera axes -->
            <origin rpy="1.5707963267948966 0 1.5707963267948966" xyz="0.0038 -0.009 0" />
            <geometry>
                <mesh filename="file:///home/iclab/work/src/camera_models/realsense2_description/meshes/d405.stl" scale="0.001 0.001 0.001" />
            </geometry>
            <material name="aluminum" />
        </visual>
        <collision>
            <origin rpy="0 0 0" xyz="-0.0078 -0.009 0" />
            <geometry>
                <box size="0.023 0.042 0.042" />
            </geometry>
        </collision>
        <inertial>
            <!-- The following are not reliable values, and should not be used for modeling -->
            <mass value="0.072" />
            <origin xyz="0 0 0" rpy="0 0 0" />
            <inertia ixx="0.003881243" ixy="0.0" ixz="0.0" iyy="0.000498940" iyz="0.0" izz="0.003879257" />
        </inertial>
    </link>
    <!-- camera depth joints and links -->
    <joint name="camera_depth_joint" type="fixed">
        <origin rpy="0 0 0" xyz="0 0 0" />
        <parent link="camera_link" />
        <child link="camera_depth_frame" />
    </joint>
    <link name="camera_depth_frame" />
    <joint name="camera_depth_optical_joint" type="fixed">
        <origin rpy="-1.5707963267948966 0 -1.5707963267948966" xyz="0 0 0" />
        <parent link="camera_depth_frame" />
        <child link="camera_depth_optical_frame" />
    </joint>
    <link name="camera_depth_optical_frame" />
    <!-- camera left IR joints and links -->
    <joint name="camera_infra1_joint" type="fixed">
        <origin rpy="0 0 0" xyz="0 0.0 0" />
        <parent link="camera_link" />
        <child link="camera_infra1_frame" />
    </joint>
    <link name="camera_infra1_frame" />
    <joint name="camera_infra1_optical_joint" type="fixed">
        <origin rpy="-1.5707963267948966 0 -1.5707963267948966" xyz="0 0 0" />
        <parent link="camera_infra1_frame" />
        <child link="camera_infra1_optical_frame" />
    </joint>
    <link name="camera_infra1_optical_frame" />
    <!-- camera right IR joints and links -->
    <joint name="camera_infra2_joint" type="fixed">
        <origin rpy="0 0 0" xyz="0 -0.018 0" />
        <parent link="camera_link" />
        <child link="camera_infra2_frame" />
    </joint>
    <link name="camera_infra2_frame" />
    <joint name="camera_infra2_optical_joint" type="fixed">
        <origin rpy="-1.5707963267948966 0 -1.5707963267948966" xyz="0 0 0" />
        <parent link="camera_infra2_frame" />
        <child link="camera_infra2_optical_frame" />
    </joint>
    <link name="camera_infra2_optical_frame" />
    <!-- camera color joints and links -->
    <joint name="camera_color_joint" type="fixed">
        <origin rpy="0 0 0" xyz="0 0.0 0" />
        <parent link="camera_link" />
        <child link="camera_color_frame" />
    </joint>
    <link name="camera_color_frame" />
    <joint name="camera_color_optical_joint" type="fixed">
        <origin rpy="-1.5707963267948966 0 -1.5707963267948966" xyz="0 0 0" />
        <parent link="camera_color_frame" />
        <child link="camera_color_optical_frame" />
    </joint>
    <link name="camera_color_optical_frame" />
    <ros2_control name="single_arm_ros2_control" type="system">
        <hardware>
            <plugin>dynamixel_hardware/DynamixelHardware</plugin>
            <param name="usb_port">/dev/ttyUSB0</param>
            <param name="baud_rate">115200</param>
            <param name="use_dummy">true</param>
        </hardware>
        <joint name="joint_1">
            <param name="id">1</param>
            <command_interface name="position" />
            <command_interface name="velocity" />
            <state_interface name="position" />
            <state_interface name="velocity" />
            <state_interface name="effort" />
        </joint>
        <joint name="joint_2">
            <param name="id">2</param>
            <command_interface name="position" />
            <command_interface name="velocity" />
            <state_interface name="position" />
            <state_interface name="velocity" />
            <state_interface name="effort" />
        </joint>
        <joint name="joint_3">
            <param name="id">3</param>
            <command_interface name="position" />
            <command_interface name="velocity" />
            <state_interface name="position" />
            <state_interface name="velocity" />
            <state_interface name="effort" />
        </joint>
        <joint name="joint_4">
            <param name="id">4</param>
            <command_interface name="position" />
            <command_interface name="velocity" />
            <state_interface name="position" />
            <state_interface name="velocity" />
            <state_interface name="effort" />
        </joint>
        <joint name="joint_5">
            <param name="id">5</param>
            <command_interface name="position" />
            <command_interface name="velocity" />
            <state_interface name="position" />
            <state_interface name="velocity" />
            <state_interface name="effort" />
        </joint>
        <joint name="joint_6">
            <param name="id">6</param>
            <command_interface name="position" />
            <command_interface name="velocity" />
            <state_interface name="position" />
            <state_interface name="velocity" />
            <state_interface name="effort" />
        </joint>
        <joint name="joint_7">
            <param name="id">7</param>
            <command_interface name="position" />
            <command_interface name="velocity" />
            <state_interface name="position" />
            <state_interface name="velocity" />
            <state_interface name="effort" />
        </joint>
    </ros2_control>
    <transmission name="trans_joint_1">
        <type>transmission_interface/SimpleTransmission</type>
        <joint name="joint_1">
            <hardwareInterface>hardware_interface/EffortJointInterface</hardwareInterface>
        </joint>
        <actuator name="joint_1_motor">
            <hardwareInterface>hardware_interface/EffortJointInterface</hardwareInterface>
            <mechanicalReduction>1</mechanicalReduction>
        </actuator>
    </transmission>
    <transmission name="trans_joint_2">
        <type>transmission_interface/SimpleTransmission</type>
        <joint name="joint_2">
            <hardwareInterface>hardware_interface/EffortJointInterface</hardwareInterface>
        </joint>
        <actuator name="joint_2_motor">
            <hardwareInterface>hardware_interface/EffortJointInterface</hardwareInterface>
            <mechanicalReduction>1</mechanicalReduction>
        </actuator>
    </transmission>
    <transmission name="trans_joint_3">
        <type>transmission_interface/SimpleTransmission</type>
        <joint name="joint_3">
            <hardwareInterface>hardware_interface/EffortJointInterface</hardwareInterface>
        </joint>
        <actuator name="joint_3_motor">
            <hardwareInterface>hardware_interface/EffortJointInterface</hardwareInterface>
            <mechanicalReduction>1</mechanicalReduction>
        </actuator>
    </transmission>
    <transmission name="trans_joint_4">
        <type>transmission_interface/SimpleTransmission</type>
        <joint name="joint_4">
            <hardwareInterface>hardware_interface/EffortJointInterface</hardwareInterface>
        </joint>
        <actuator name="joint_4_motor">
            <hardwareInterface>hardware_interface/EffortJointInterface</hardwareInterface>
            <mechanicalReduction>1</mechanicalReduction>
        </actuator>
    </transmission>
    <transmission name="trans_joint_5">
        <type>transmission_interface/SimpleTransmission</type>
        <joint name="joint_5">
            <hardwareInterface>hardware_interface/EffortJointInterface</hardwareInterface>
        </joint>
        <actuator name="joint_5_motor">
            <hardwareInterface>hardware_interface/EffortJointInterface</hardwareInterface>
            <mechanicalReduction>1</mechanicalReduction>
        </actuator>
    </transmission>
    <transmission name="trans_joint_6">
        <type>transmission_interface/SimpleTransmission</type>
        <joint name="joint_6">
            <hardwareInterface>hardware_interface/EffortJointInterface</hardwareInterface>
        </joint>
        <actuator name="joint_6_motor">
            <hardwareInterface>hardware_interface/EffortJointInterface</hardwareInterface>
            <mechanicalReduction>1</mechanicalReduction>
        </actuator>
    </transmission>
    <transmission name="trans_joint_7">
        <type>transmission_interface/SimpleTransmission</type>
        <joint name="joint_7">
            <hardwareInterface>hardware_interface/EffortJointInterface</hardwareInterface>
        </joint>
        <actuator name="joint_7_motor">
            <hardwareInterface>hardware_interface/EffortJointInterface</hardwareInterface>
            <mechanicalReduction>1</mechanicalReduction>
        </actuator>
    </transmission>
    <gazebo>
        <plugin name="gazebo_ros_control">
            <robotNamespace>/</robotNamespace>
        </plugin>
    </gazebo>
</robot>

