<?xml version="1.0" ?>
<!-- =================================================================================== -->
<!-- |    This document was autogenerated by xacro from /home/iclab/work/src/manipulability_metrics_examples/urdf/timda_dual7.xacro | -->
<!-- |    EDITING THIS FILE BY HAND IS NOT RECOMMENDED                                 | -->
<!-- =================================================================================== -->
<robot name="mobile_dual_arm">
    <!-- <xacro:include filename="$(find timda_body)/urdf/timda_body.gazebo.xacro" /> -->
    <link name="base_link">
        <inertial>
            <origin rpy="0 0 0" xyz="0.0 0 0" />
            <mass value="2.072" />
            <inertia ixx="1" ixy="0" ixz="0" iyy="1" iyz="0" izz="1" />
        </inertial>
        <visual>
            <origin rpy="0 0 0" xyz="0 0 0" />
            <geometry>
                <mesh filename="package://timda_body/meshes/base_link.STL" />
            </geometry>
            <material name="">
                <color rgba="0.79216 0.81961 0.93333 1" />
            </material>
        </visual>
        <collision>
            <origin rpy="0 0 0" xyz="0 0 0" />
            <geometry>
                <mesh filename="package://timda_body/meshes/base_link.STL" />
            </geometry>
        </collision>
    </link>
    <link name="slide_right">
        <inertial>
            <origin rpy="0 0 0" xyz="1.5718E-05 -0.006626 2.4586E-06" />
            <mass value="0.24709" />
            <inertia ixx="1" ixy="0" ixz="0" iyy="1" iyz="0" izz="1" />
        </inertial>
        <visual>
            <origin rpy="0 0 0" xyz="0 0 0" />
            <geometry>
                <mesh filename="package://timda_body/meshes/slide_right.STL" />
            </geometry>
            <material name="">
                <color rgba="0.89804 0.91765 0.92941 1" />
            </material>
        </visual>
        <collision>
            <origin rpy="0 0 0" xyz="0 0 0" />
            <geometry>
                <mesh filename="package://timda_body/meshes/slide_right.STL" />
            </geometry>
        </collision>
    </link>
    <joint name="joint_right" type="fixed">
        <origin rpy="0 0 0" xyz="-0.2 0.0765 1.1815" />
        <parent link="base_link" />
        <child link="slide_right" />
    </joint>
    <link name="slide_left">
        <inertial>
            <origin rpy="0 0 0" xyz="-1.5722E-05 0.006626 2.4586E-06" />
            <mass value="0.24709" />
            <inertia ixx="1" ixy="0" ixz="0" iyy="1" iyz="0" izz="1" />
        </inertial>
        <visual>
            <origin rpy="0 0 0" xyz="0 0 0" />
            <geometry>
                <mesh filename="package://timda_body/meshes/slide_right.STL" />
            </geometry>
            <material name="">
                <color rgba="0.89804 0.91765 0.92941 1" />
            </material>
        </visual>
        <collision>
            <origin rpy="0 0 0" xyz="0 0 0" />
            <geometry>
                <mesh filename="package://timda_body/meshes/slide_right.STL" />
            </geometry>
        </collision>
    </link>
    <joint name="joint_left" type="fixed">
        <origin rpy="0 0 3.1416" xyz="-0.2 -0.0765 1.1815" />
        <parent link="base_link" />
        <child link="slide_left" />
    </joint>
    <material name="black">
        <color rgba="0.0 0.0 0.0 1.0" />
    </material>
    <material name="blue">
        <color rgba="0.0 0.0 0.8 1.0" />
    </material>
    <material name="green">
        <color rgba="0.0 0.8 0.0 1.0" />
    </material>
    <material name="grey">
        <color rgba="0.2 0.2 0.2 1.0" />
    </material>
    <material name="orange">
        <color rgba="1.0 0.4235294117647059 0.0392156862745098 1.0" />
    </material>
    <material name="brown">
        <color rgba="0.8705882352941177 0.8117647058823529 0.7647058823529411 1.0" />
    </material>
    <material name="red">
        <color rgba="0.8 0.0 0.0 1.0" />
    </material>
    <material name="white">
        <color rgba="1.0 1.0 1.0 1.0" />
    </material>
    <!-- Constants for robot dimensions -->
    <!-- <xacro:include filename="$(find suction_urdf)/urdf/suction.transmission.xacro" />
  <xacro:include filename="$(find suction_urdf)/urdf/suction.gazebo.xacro" /> -->
    <link name="world" />
    <!-- TIMDA body -->
    <joint name="fixed1" type="fixed">
        <origin rpy="0 0 0" xyz="0 0 0" />
        <parent link="world" />
        <child link="base_link" />
    </joint>
    <joint name="r_fixed" type="fixed">
        <origin rpy="1.57 3.1415926 3.1415926" xyz="0.0 0.1151 0.0" />
        <parent link="slide_right" />
        <child link="r_base" />
    </joint>
    <link name="r_base">
        <inertial>
            <origin rpy="0 0 0" xyz="0.000156250860732315 0.000202963757501797 -0.0546720420122521" />
            <mass value="0.323603974032196" />
            <inertia ixx="0.1" ixy="0.0" ixz="0.0" iyy="0.1" iyz="0.0" izz="0.1" />
        </inertial>
        <visual>
            <origin rpy="0 0 0" xyz="0 0 0" />
            <geometry>
                <mesh filename="package://single_arm_description/meshes/base.STL" />
            </geometry>
            <material name="grey">
                <!-- <color 
					rgba="0.792156862745098 0.819607843137255 0.933333333333333 1" /> -->
            </material>
        </visual>
        <collision>
            <origin rpy="0 0 0" xyz="0 0 0" />
            <geometry>
                <mesh filename="package://single_arm_description/meshes/base.STL" />
            </geometry>
        </collision>
    </link>
    <joint name="r_joint_1" type="revolute">
        <origin rpy="-1.5707963267949 -2.60398896659329E-32 1.5707963267949" xyz="0 0 0.0550000000000002" />
        <parent link="r_base" />
        <child link="r_link_1" />
        <axis xyz="0 -1 0" />
        <limit effort="1000" lower="-3.14" upper="3.14" velocity="6.5" />
        <dynamics damping="0.7" />
    </joint>
    <link name="r_link_1">
        <inertial>
            <origin rpy="0 0 0" xyz="-3.64540734812575E-06 0.00119778550610652 -0.000421399675048756" />
            <mass value="0.386131223153925" />
            <inertia ixx="0.1" ixy="0.0" ixz="0.0" iyy="0.1" iyz="0.0" izz="0.1" />
        </inertial>
        <visual>
            <origin rpy="0 0 0" xyz="0 0 0" />
            <geometry>
                <mesh filename="package://single_arm_description/meshes/link_1.STL" />
            </geometry>
            <material name="grey">
                <!-- <color
		  		rgba="0.898039215686275 0.917647058823529 0.929411764705882 1" /> -->
            </material>
        </visual>
        <collision>
            <origin rpy="0 0 0" xyz="0 0 0" />
            <geometry>
                <mesh filename="package://single_arm_description/meshes/link_1.STL" />
            </geometry>
        </collision>
    </link>
    <joint name="r_joint_2" type="revolute">
        <origin rpy="-1.5707963267949 7.39557098644699E-32 -1.5707963267949" xyz="0 0 0" />
        <parent link="r_link_1" />
        <child link="r_link_2" />
        <axis xyz="0 -1 0" />
        <limit effort="1000" lower="-3.14" upper="3.14" velocity="6.5" />
        <dynamics damping="0.7" />
    </joint>
    <link name="r_link_2">
        <inertial>
            <origin rpy="0 0 0" xyz="0.000683310419598862 -8.00535195483731E-05 0.117541995924546" />
            <mass value="0.479430893999342" />
            <inertia ixx="0.1" ixy="0.0" ixz="0.0" iyy="0.1" iyz="0.0" izz="0.1" />
        </inertial>
        <visual>
            <origin rpy="0 0 0" xyz="0 0 0" />
            <geometry>
                <mesh filename="package://single_arm_description/meshes/link_2.STL" />
            </geometry>
            <material name="grey">
                <!-- <color
		  		rgba="0.898039215686275 0.917647058823529 0.929411764705882 1" /> -->
            </material>
        </visual>
        <collision>
            <origin rpy="0 0 0" xyz="0 0 0" />
            <geometry>
                <mesh filename="package://single_arm_description/meshes/link_2.STL" />
            </geometry>
        </collision>
    </link>
    <joint name="r_joint_3" type="revolute">
        <origin rpy="1.5707963267949 4.63843178081015E-17 6.91111242388425E-16" xyz="0 0 0.174" />
        <parent link="r_link_2" />
        <child link="r_link_3" />
        <axis xyz="0 1 0" />
        <limit effort="1000" lower="-3.14" upper="3.14" velocity="6.5" />
        <dynamics damping="0.7" />
    </joint>
    <link name="r_link_3">
        <inertial>
            <origin rpy="0 0 0" xyz="-0.0220564838621471 0.101455973505417 -8.62457453022769E-05" />
            <mass value="0.568306813792926" />
            <inertia ixx="0.1" ixy="0.0" ixz="0.0" iyy="0.1" iyz="0.0" izz="0.1" />
        </inertial>
        <visual>
            <origin rpy="0 0 0" xyz="0 0 0" />
            <geometry>
                <mesh filename="package://single_arm_description/meshes/link_3.STL" />
            </geometry>
            <material name="grey">
                <!-- <color
		  		rgba="0.898039215686275 0.917647058823529 0.929411764705882 1" /> -->
            </material>
        </visual>
        <collision>
            <origin rpy="0 0 0" xyz="0 0 0" />
            <geometry>
                <mesh filename="package://single_arm_description/meshes/link_3.STL" />
            </geometry>
        </collision>
    </link>
    <joint name="r_joint_4" type="revolute">
        <origin rpy="-1.5707963267949 -1.40443212615082E-14 1.75438367537121E-15" xyz="-0.0299999998727122 0.115999993001519 0.0359999999999999" />
        <parent link="r_link_3" />
        <child link="r_link_4" />
        <axis xyz="0 -1 0" />
        <limit effort="1000" lower="-3.14" upper="3.14" velocity="6.5" />
        <dynamics damping="0.7" />
    </joint>
    <link name="r_link_4">
        <inertial>
            <origin rpy="0 0 0" xyz="0.0297389855299131 0.0361651889050357 0.108377256276242" />
            <mass value="0.457613402476782" />
            <inertia ixx="0.1" ixy="0.0" ixz="0.0" iyy="0.1" iyz="0.0" izz="0.1" />
        </inertial>
        <visual>
            <origin rpy="0 0 0" xyz="0 0 0" />
            <geometry>
                <mesh filename="package://single_arm_description/meshes/link_4.STL" />
            </geometry>
            <material name="grey">
                <!-- <color
		  		rgba="0.898039215686275 0.917647058823529 0.929411764705882 1" /> -->
            </material>
        </visual>
        <collision>
            <origin rpy="0 0 0" xyz="0 0 0" />
            <geometry>
                <mesh filename="package://single_arm_description/meshes/link_4.STL" />
            </geometry>
        </collision>
    </link>
    <joint name="r_joint_5" type="revolute">
        <origin rpy="1.5707963267949 -8.80083043478898E-16 -2.49800180540655E-16" xyz="0.029999999872713 0.0359999999999987 0.162" />
        <parent link="r_link_4" />
        <child link="r_link_5" />
        <axis xyz="0 1 0" />
        <limit effort="1000" lower="-3.14" upper="3.14" velocity="6.5" />
        <dynamics damping="0.7" />
    </joint>
    <link name="r_link_5">
        <inertial>
            <origin rpy="0 0 0" xyz="-0.000172095429412281 0.102690028206534 -6.66794215013755E-05" />
            <mass value="0.448277275798768" />
            <inertia ixx="0.1" ixy="0.0" ixz="0.0" iyy="0.1" iyz="0.0" izz="0.1" />
        </inertial>
        <visual>
            <origin rpy="0 0 0" xyz="0 0 0" />
            <geometry>
                <mesh filename="package://single_arm_description/meshes/link_5.STL" />
            </geometry>
            <material name="grey">
                <!-- <color
		  		rgba="0.792156862745098 0.819607843137255 0.933333333333333 1" /> -->
            </material>
        </visual>
        <collision>
            <origin rpy="0 0 0" xyz="0 0 0" />
            <geometry>
                <mesh filename="package://single_arm_description/meshes/link_5.STL" />
            </geometry>
        </collision>
    </link>
    <joint name="r_joint_6" type="revolute">
        <origin rpy="-1.5707963267949 0 4.46815747097797E-32" xyz="0 0.108000511190835 0.0360000000000014" />
        <parent link="r_link_5" />
        <child link="r_link_6" />
        <axis xyz="0 -1 0" />
        <limit effort="1000" lower="-3.14" upper="3.14" velocity="6.5" />
        <dynamics damping="0.7" />
    </joint>
    <link name="r_link_6">
        <inertial>
            <origin rpy="0 0 0" xyz="1.14707347786958E-08 0.0359051244401507 0.076720238383497" />
            <mass value="0.205818407044008" />
            <inertia ixx="0.1" ixy="0.0" ixz="0.0" iyy="0.1" iyz="0.0" izz="0.1" />
        </inertial>
        <visual>
            <origin rpy="0 0 0" xyz="0 0 0" />
            <geometry>
                <mesh filename="package://single_arm_description/meshes/link_6.STL" />
            </geometry>
            <material name="grey">
                <!-- <color
		  		rgba="0.898039215686275 0.917647058823529 0.929411764705882 1" /> -->
            </material>
        </visual>
        <collision>
            <origin rpy="0 0 0" xyz="0 0 0" />
            <geometry>
                <mesh filename="package://single_arm_description/meshes/link_6.STL" />
            </geometry>
        </collision>
    </link>
    <!-- <link
	    name="${side}link_7">
	    <inertial>
	      <origin
		xyz="-0.00300603996967419 -5.54762008899146E-05 0.256296304324454"
		rpy="0 0 0" />
	      <mass
		value="0.0968605125725848" />
	      <inertia
		ixx="0.000598660550174727"
		ixy="1.6879862442818E-08"
		ixz="-2.31313376077572E-05"
		iyy="0.000605976408521062"
		iyz="1.75519608508907E-07"
		izz="2.73730335090959E-05" />
	    </inertial>
	    <visual>
	      <origin
		xyz="0 0 0"
		rpy="0 0 0" />
	      <geometry>
		<mesh
		  filename="package://single_arm_description/meshes/link_7.STL" />
	      </geometry>
	      <material
		name="">
		<color
		  rgba="1 1 1 1" />
	      </material>
	    </visual>
	    <collision>
	      <origin
		xyz="0 0 0"
		rpy="0 0 0" />
	      <geometry>
		<mesh
		  filename="package://single_arm_description/meshes/link_7.STL" />
	      </geometry>
	    </collision>
	  </link> -->
    <!-- <xacro:if value="${'link' in child}">
		<joint
			name="${side}joint_7"
			type="revolute">
			<origin
				xyz="0 0.03680 0.135"
				rpy="0 0 ${toolrot}" /> -->
    <!-- rpy="1.5708 ${toolrot} 0" /> -->
    <!-- xyz="-0.008041 0.038 0.13545" -->
    <!-- xyz="-0.0025 0.038 0.135" -->
    <!-- <parent
				link="${side}link_6" />
			<child
				link="${child}" />
			<axis 
				xyz="0 0 1" />
			<limit
				lower="-3.14"
				upper="3.14"
				effort="1000"
                velocity="6.5" />
          <dynamics damping="0.7"/>
		</joint>
    </xacro:if> -->
    <joint name="r_joint_7" type="revolute">
        <origin rpy="0 0 -1.57" xyz="0 0.03680 0.135" />
        <!-- rpy="1.5708 ${toolrot} 0" /> -->
        <!-- xyz="-0.008041 0.038 0.13545" -->
        <!-- xyz="-0.0025 0.038 0.135" -->
        <parent link="r_link_6" />
        <child link="r_tool_link" />
        <axis xyz="0 0 1" />
        <limit effort="1000" lower="-3.14" upper="3.14" velocity="6.5" />
        <dynamics damping="0.7" />
    </joint>
    <!--
	  <link
	    name="${side}link_8">
	    <inertial>
	      <origin
		xyz="9.57945038487507E-05 -0.00931752529150576 -0.00542544640949998"
		rpy="0 0 0" />
	      <mass
		value="0.0130047980464835" />
	      <inertia
		ixx="2.46491406196035E-06"
		ixy="2.73921418079654E-09"
		ixz="-1.30294079932031E-08"
		iyy="1.47440149396087E-06"
		iyz="6.68439506061302E-07"
		izz="2.1558209563788E-06" />
	    </inertial>
	    <visual>
	      <origin
		xyz="0 0 0"
		rpy="0 0 0" />
	      <geometry>
		<mesh
		  filename="package://single_arm_description/meshes/link_8.STL" />
	      </geometry>
	      <material
		name="">
		<color
		  rgba="0.792156862745098 0.819607843137255 0.933333333333333 1" />
	      </material>
	    </visual>
	    <collision>
	      <origin
		xyz="0 0 0"
		rpy="0 0 0" />
	      <geometry>
		<mesh
		  filename="package://single_arm_description/meshes/link_8.STL" />
	      </geometry>
	    </collision>
	  </link>
	  <joint
	    name="${side}joint_8"
	    type="revolute">
	    <origin
	      xyz="0 0 0.3985"
	      rpy="-1.5708 0 0" />
	    <parent
	      link="${side}link_7" />
	    <child
	      link="${side}link_8" />
	    <axis
	      xyz="0 0 -1" />
	    <limit
	      lower="-3.14"
	      upper="3.14"
	      effort="2"
	      velocity="2" />
	  </joint>
	-->
    <!-- <xacro:single_arm_transmission side="${side}" />
	  <xacro:single_arm_gazebo side="${side}" /> -->
    <link name="r_tool_link">
        <inertial>
            <origin rpy="0 0 0" xyz="-0.003041 0.0027723 0.043545" />
            <mass value="0.11123" />
            <inertia ixx="0.1" ixy="0.0" ixz="0.0" iyy="0.1" iyz="0.0" izz="0.1" />
        </inertial>
        <visual>
            <origin rpy="0 0 0" xyz="0 0 0" />
            <geometry>
                <mesh filename="package://suction_urdf/meshes/tool_link.STL" />
            </geometry>
            <material name="">
                <color rgba="1 1 1 1" />
            </material>
        </visual>
        <collision>
            <origin rpy="0 0 0" xyz="0 0 0" />
            <geometry>
                <mesh filename="package://suction_urdf/meshes/tool_link.STL" />
            </geometry>
        </collision>
    </link>
    <link name="r_tool_end_Link">
        <inertial>
            <origin rpy="0 0 0" xyz="9.909E-05 0.0039906 0.025651" />
            <mass value="0.033438" />
            <inertia ixx="0.1" ixy="0.0" ixz="0.0" iyy="0.1" iyz="0.0" izz="0.1" />
        </inertial>
        <visual>
            <origin rpy="0 0 0" xyz="0 0 0" />
            <geometry>
                <mesh filename="package://suction_urdf/meshes/tool_end_Link.STL" />
            </geometry>
            <material name="">
                <color rgba="0.79216 0.81961 0.93333 1" />
            </material>
        </visual>
        <collision>
            <origin rpy="0 0 0" xyz="0 0 0" />
            <geometry>
                <mesh filename="package://suction_urdf/meshes/tool_end_Link.STL" />
            </geometry>
        </collision>
    </link>
    <joint name="r_tool_joint" type="revolute">
        <origin rpy="-1.7985E-15 -2.9973E-16 1.1669E-16" xyz="0 0.002 0.1045" />
        <parent link="r_tool_link" />
        <child link="r_tool_end_Link" />
        <axis xyz="0 1 0" />
        <limit effort="1000" lower="-3.14" upper="3.14" velocity="6.5" />
        <dynamics damping="0.7" />
    </joint>
    <link name="r_end_Link1">
        <gravity>0</gravity>
        <inertial>
            <origin rpy="0 0 0" xyz="0 0 0" />
            <mass value="0.0001" />
            <inertia ixx="0.0001" ixy="0.000" ixz="0.000" iyy="0.0001" iyz="0.000" izz="0.0001" />
        </inertial>
        <visual>
            <origin rpy="0 0 0" xyz="0 0 0" />
            <geometry>
                <box size="0.01 0.01 0.01" />
            </geometry>
            <material name="transparent">
                <color rgba="0 0 0 0" />
            </material>
        </visual>
    </link>
    <joint name="r_end_joint1" type="revolute">
        <origin rpy="0 1.5708 0" xyz="0 -0.001 0.06" />
        <parent link="r_tool_end_Link" />
        <child link="r_end_Link1" />
        <axis xyz="1 0 0" />
        <limit effort="1000" lower="0" upper="0" velocity="6.5" />
        <dynamics damping="0.0" friction="10" />
    </joint>
    <link name="r_end_Link2">
        <gravity>0</gravity>
        <inertial>
            <origin rpy="0 0 0" xyz="0 0 0" />
            <mass value="0.0001" />
            <inertia ixx="0.0001" ixy="0.000" ixz="0.000" iyy="0.0001" iyz="0.000" izz="0.0001" />
        </inertial>
        <visual>
            <origin rpy="0 0 0" xyz="0 0 0" />
            <geometry>
                <box size="0.01 0.01 0.01" />
            </geometry>
            <material name="transparent">
                <color rgba="0 0 0 0" />
            </material>
        </visual>
    </link>
    <joint name="r_end_joint2" type="revolute">
        <origin rpy="0 1.5708 0" xyz="-0.0125 -0.001 0.06" />
        <parent link="r_tool_end_Link" />
        <child link="r_end_Link2" />
        <axis xyz="1 0 0" />
        <limit effort="1000" lower="0" upper="0" velocity="6.5" />
        <dynamics damping="0.0" friction="10" />
    </joint>
    <link name="r_end_Link3">
        <gravity>0</gravity>
        <inertial>
            <origin rpy="0 0 0" xyz="0 0 0" />
            <mass value="0.0001" />
            <inertia ixx="0.0001" ixy="0.000" ixz="0.000" iyy="0.0001" iyz="0.000" izz="0.0001" />
        </inertial>
        <visual>
            <origin rpy="0 0 0" xyz="0 0 0" />
            <geometry>
                <box size="0.01 0.01 0.01" />
            </geometry>
            <material name="transparent">
                <color rgba="0 0 0 0" />
            </material>
        </visual>
    </link>
    <joint name="r_end_joint3" type="revolute">
        <origin rpy="0 1.5708 0" xyz="0.0125 -0.001 0.06" />
        <parent link="r_tool_end_Link" />
        <child link="r_end_Link3" />
        <axis xyz="1 0 0" />
        <limit effort="1000" lower="0" upper="0" velocity="6.5" />
        <dynamics damping="0.0" friction="10" />
    </joint>
    <link name="r_end_Link4">
        <gravity>0</gravity>
        <inertial>
            <origin rpy="0 0 0" xyz="0 0 0" />
            <mass value="0.0001" />
            <inertia ixx="0.0001" ixy="0.000" ixz="0.000" iyy="0.0001" iyz="0.000" izz="0.0001" />
        </inertial>
        <visual>
            <origin rpy="0 0 0" xyz="0 0 0" />
            <geometry>
                <box size="0.01 0.01 0.01" />
            </geometry>
            <material name="transparent">
                <color rgba="0 0 0 0" />
            </material>
        </visual>
    </link>
    <joint name="r_end_joint4" type="revolute">
        <origin rpy="0 1.5708 0" xyz="0 -0.001 0.0475" />
        <parent link="r_tool_end_Link" />
        <child link="r_end_Link4" />
        <axis xyz="1 0 0" />
        <limit effort="1000" lower="0" upper="0" velocity="6.5" />
        <dynamics damping="0.0" friction="10" />
    </joint>
    <link name="r_end_Link5">
        <gravity>0</gravity>
        <inertial>
            <origin rpy="0 0 0" xyz="0 0 0" />
            <mass value="0.0001" />
            <inertia ixx="0.0001" ixy="0.000" ixz="0.000" iyy="0.0001" iyz="0.000" izz="0.0001" />
        </inertial>
        <visual>
            <origin rpy="0 0 0" xyz="0 0 0" />
            <geometry>
                <box size="0.01 0.01 0.01" />
            </geometry>
            <material name="transparent">
                <color rgba="0 0 0 0" />
            </material>
        </visual>
    </link>
    <joint name="r_end_joint5" type="revolute">
        <origin rpy="0 1.5708 0" xyz="0 -0.001 0.0725" />
        <parent link="r_tool_end_Link" />
        <child link="r_end_Link5" />
        <axis xyz="1 0 0" />
        <limit effort="1000" lower="0" upper="0" velocity="6.5" />
        <dynamics damping="0.0" friction="10" />
    </joint>
    <!-- <xacro:suction_transmission side="${side}" />
    <xacro:suction_gazebo side="${side}" /> -->
    <joint name="l_fixed" type="fixed">
        <origin rpy="-1.57 0 0" xyz="0.0 0.1151 0.0" />
        <parent link="slide_left" />
        <child link="l_base" />
    </joint>
    <link name="l_base">
        <inertial>
            <origin rpy="0 0 0" xyz="0.000156250860732315 0.000202963757501797 -0.0546720420122521" />
            <mass value="0.323603974032196" />
            <inertia ixx="0.1" ixy="0.0" ixz="0.0" iyy="0.1" iyz="0.0" izz="0.1" />
        </inertial>
        <visual>
            <origin rpy="0 0 0" xyz="0 0 0" />
            <geometry>
                <mesh filename="package://single_arm_description/meshes/base.STL" />
            </geometry>
            <material name="grey">
                <!-- <color 
					rgba="0.792156862745098 0.819607843137255 0.933333333333333 1" /> -->
            </material>
        </visual>
        <collision>
            <origin rpy="0 0 0" xyz="0 0 0" />
            <geometry>
                <mesh filename="package://single_arm_description/meshes/base.STL" />
            </geometry>
        </collision>
    </link>
    <joint name="l_joint_1" type="revolute">
        <origin rpy="-1.5707963267949 -2.60398896659329E-32 1.5707963267949" xyz="0 0 0.0550000000000002" />
        <parent link="l_base" />
        <child link="l_link_1" />
        <axis xyz="0 -1 0" />
        <limit effort="1000" lower="-3.14" upper="3.14" velocity="6.5" />
        <dynamics damping="0.7" />
    </joint>
    <link name="l_link_1">
        <inertial>
            <origin rpy="0 0 0" xyz="-3.64540734812575E-06 0.00119778550610652 -0.000421399675048756" />
            <mass value="0.386131223153925" />
            <inertia ixx="0.1" ixy="0.0" ixz="0.0" iyy="0.1" iyz="0.0" izz="0.1" />
        </inertial>
        <visual>
            <origin rpy="0 0 0" xyz="0 0 0" />
            <geometry>
                <mesh filename="package://single_arm_description/meshes/link_1.STL" />
            </geometry>
            <material name="grey">
                <!-- <color
		  		rgba="0.898039215686275 0.917647058823529 0.929411764705882 1" /> -->
            </material>
        </visual>
        <collision>
            <origin rpy="0 0 0" xyz="0 0 0" />
            <geometry>
                <mesh filename="package://single_arm_description/meshes/link_1.STL" />
            </geometry>
        </collision>
    </link>
    <joint name="l_joint_2" type="revolute">
        <origin rpy="-1.5707963267949 7.39557098644699E-32 -1.5707963267949" xyz="0 0 0" />
        <parent link="l_link_1" />
        <child link="l_link_2" />
        <axis xyz="0 -1 0" />
        <limit effort="1000" lower="-3.14" upper="3.14" velocity="6.5" />
        <dynamics damping="0.7" />
    </joint>
    <link name="l_link_2">
        <inertial>
            <origin rpy="0 0 0" xyz="0.000683310419598862 -8.00535195483731E-05 0.117541995924546" />
            <mass value="0.479430893999342" />
            <inertia ixx="0.1" ixy="0.0" ixz="0.0" iyy="0.1" iyz="0.0" izz="0.1" />
        </inertial>
        <visual>
            <origin rpy="0 0 0" xyz="0 0 0" />
            <geometry>
                <mesh filename="package://single_arm_description/meshes/link_2.STL" />
            </geometry>
            <material name="grey">
                <!-- <color
		  		rgba="0.898039215686275 0.917647058823529 0.929411764705882 1" /> -->
            </material>
        </visual>
        <collision>
            <origin rpy="0 0 0" xyz="0 0 0" />
            <geometry>
                <mesh filename="package://single_arm_description/meshes/link_2.STL" />
            </geometry>
        </collision>
    </link>
    <joint name="l_joint_3" type="revolute">
        <origin rpy="1.5707963267949 4.63843178081015E-17 6.91111242388425E-16" xyz="0 0 0.174" />
        <parent link="l_link_2" />
        <child link="l_link_3" />
        <axis xyz="0 1 0" />
        <limit effort="1000" lower="-3.14" upper="3.14" velocity="6.5" />
        <dynamics damping="0.7" />
    </joint>
    <link name="l_link_3">
        <inertial>
            <origin rpy="0 0 0" xyz="-0.0220564838621471 0.101455973505417 -8.62457453022769E-05" />
            <mass value="0.568306813792926" />
            <inertia ixx="0.1" ixy="0.0" ixz="0.0" iyy="0.1" iyz="0.0" izz="0.1" />
        </inertial>
        <visual>
            <origin rpy="0 0 0" xyz="0 0 0" />
            <geometry>
                <mesh filename="package://single_arm_description/meshes/link_3.STL" />
            </geometry>
            <material name="grey">
                <!-- <color
		  		rgba="0.898039215686275 0.917647058823529 0.929411764705882 1" /> -->
            </material>
        </visual>
        <collision>
            <origin rpy="0 0 0" xyz="0 0 0" />
            <geometry>
                <mesh filename="package://single_arm_description/meshes/link_3.STL" />
            </geometry>
        </collision>
    </link>
    <joint name="l_joint_4" type="revolute">
        <origin rpy="-1.5707963267949 -1.40443212615082E-14 1.75438367537121E-15" xyz="-0.0299999998727122 0.115999993001519 0.0359999999999999" />
        <parent link="l_link_3" />
        <child link="l_link_4" />
        <axis xyz="0 -1 0" />
        <limit effort="1000" lower="-3.14" upper="3.14" velocity="6.5" />
        <dynamics damping="0.7" />
    </joint>
    <link name="l_link_4">
        <inertial>
            <origin rpy="0 0 0" xyz="0.0297389855299131 0.0361651889050357 0.108377256276242" />
            <mass value="0.457613402476782" />
            <inertia ixx="0.1" ixy="0.0" ixz="0.0" iyy="0.1" iyz="0.0" izz="0.1" />
        </inertial>
        <visual>
            <origin rpy="0 0 0" xyz="0 0 0" />
            <geometry>
                <mesh filename="package://single_arm_description/meshes/link_4.STL" />
            </geometry>
            <material name="grey">
                <!-- <color
		  		rgba="0.898039215686275 0.917647058823529 0.929411764705882 1" /> -->
            </material>
        </visual>
        <collision>
            <origin rpy="0 0 0" xyz="0 0 0" />
            <geometry>
                <mesh filename="package://single_arm_description/meshes/link_4.STL" />
            </geometry>
        </collision>
    </link>
    <joint name="l_joint_5" type="revolute">
        <origin rpy="1.5707963267949 -8.80083043478898E-16 -2.49800180540655E-16" xyz="0.029999999872713 0.0359999999999987 0.162" />
        <parent link="l_link_4" />
        <child link="l_link_5" />
        <axis xyz="0 1 0" />
        <limit effort="1000" lower="-3.14" upper="3.14" velocity="6.5" />
        <dynamics damping="0.7" />
    </joint>
    <link name="l_link_5">
        <inertial>
            <origin rpy="0 0 0" xyz="-0.000172095429412281 0.102690028206534 -6.66794215013755E-05" />
            <mass value="0.448277275798768" />
            <inertia ixx="0.1" ixy="0.0" ixz="0.0" iyy="0.1" iyz="0.0" izz="0.1" />
        </inertial>
        <visual>
            <origin rpy="0 0 0" xyz="0 0 0" />
            <geometry>
                <mesh filename="package://single_arm_description/meshes/link_5.STL" />
            </geometry>
            <material name="grey">
                <!-- <color
		  		rgba="0.792156862745098 0.819607843137255 0.933333333333333 1" /> -->
            </material>
        </visual>
        <collision>
            <origin rpy="0 0 0" xyz="0 0 0" />
            <geometry>
                <mesh filename="package://single_arm_description/meshes/link_5.STL" />
            </geometry>
        </collision>
    </link>
    <joint name="l_joint_6" type="revolute">
        <origin rpy="-1.5707963267949 0 4.46815747097797E-32" xyz="0 0.108000511190835 0.0360000000000014" />
        <parent link="l_link_5" />
        <child link="l_link_6" />
        <axis xyz="0 -1 0" />
        <limit effort="1000" lower="-3.14" upper="3.14" velocity="6.5" />
        <dynamics damping="0.7" />
    </joint>
    <link name="l_link_6">
        <inertial>
            <origin rpy="0 0 0" xyz="1.14707347786958E-08 0.0359051244401507 0.076720238383497" />
            <mass value="0.205818407044008" />
            <inertia ixx="0.1" ixy="0.0" ixz="0.0" iyy="0.1" iyz="0.0" izz="0.1" />
        </inertial>
        <visual>
            <origin rpy="0 0 0" xyz="0 0 0" />
            <geometry>
                <mesh filename="package://single_arm_description/meshes/link_6.STL" />
            </geometry>
            <material name="grey">
                <!-- <color
		  		rgba="0.898039215686275 0.917647058823529 0.929411764705882 1" /> -->
            </material>
        </visual>
        <collision>
            <origin rpy="0 0 0" xyz="0 0 0" />
            <geometry>
                <mesh filename="package://single_arm_description/meshes/link_6.STL" />
            </geometry>
        </collision>
    </link>
    <!-- <link
	    name="${side}link_7">
	    <inertial>
	      <origin
		xyz="-0.00300603996967419 -5.54762008899146E-05 0.256296304324454"
		rpy="0 0 0" />
	      <mass
		value="0.0968605125725848" />
	      <inertia
		ixx="0.000598660550174727"
		ixy="1.6879862442818E-08"
		ixz="-2.31313376077572E-05"
		iyy="0.000605976408521062"
		iyz="1.75519608508907E-07"
		izz="2.73730335090959E-05" />
	    </inertial>
	    <visual>
	      <origin
		xyz="0 0 0"
		rpy="0 0 0" />
	      <geometry>
		<mesh
		  filename="package://single_arm_description/meshes/link_7.STL" />
	      </geometry>
	      <material
		name="">
		<color
		  rgba="1 1 1 1" />
	      </material>
	    </visual>
	    <collision>
	      <origin
		xyz="0 0 0"
		rpy="0 0 0" />
	      <geometry>
		<mesh
		  filename="package://single_arm_description/meshes/link_7.STL" />
	      </geometry>
	    </collision>
	  </link> -->
    <!-- <xacro:if value="${'link' in child}">
		<joint
			name="${side}joint_7"
			type="revolute">
			<origin
				xyz="0 0.03680 0.135"
				rpy="0 0 ${toolrot}" /> -->
    <!-- rpy="1.5708 ${toolrot} 0" /> -->
    <!-- xyz="-0.008041 0.038 0.13545" -->
    <!-- xyz="-0.0025 0.038 0.135" -->
    <!-- <parent
				link="${side}link_6" />
			<child
				link="${child}" />
			<axis 
				xyz="0 0 1" />
			<limit
				lower="-3.14"
				upper="3.14"
				effort="1000"
                velocity="6.5" />
          <dynamics damping="0.7"/>
		</joint>
    </xacro:if> -->
    <joint name="l_joint_7" type="revolute">
        <origin rpy="0 0 1.57" xyz="0 0.03680 0.135" />
        <!-- rpy="1.5708 ${toolrot} 0" /> -->
        <!-- xyz="-0.008041 0.038 0.13545" -->
        <!-- xyz="-0.0025 0.038 0.135" -->
        <parent link="l_link_6" />
        <child link="l_tool_link" />
        <axis xyz="0 0 1" />
        <limit effort="1000" lower="-3.14" upper="3.14" velocity="6.5" />
        <dynamics damping="0.7" />
    </joint>
    <!--
	  <link
	    name="${side}link_8">
	    <inertial>
	      <origin
		xyz="9.57945038487507E-05 -0.00931752529150576 -0.00542544640949998"
		rpy="0 0 0" />
	      <mass
		value="0.0130047980464835" />
	      <inertia
		ixx="2.46491406196035E-06"
		ixy="2.73921418079654E-09"
		ixz="-1.30294079932031E-08"
		iyy="1.47440149396087E-06"
		iyz="6.68439506061302E-07"
		izz="2.1558209563788E-06" />
	    </inertial>
	    <visual>
	      <origin
		xyz="0 0 0"
		rpy="0 0 0" />
	      <geometry>
		<mesh
		  filename="package://single_arm_description/meshes/link_8.STL" />
	      </geometry>
	      <material
		name="">
		<color
		  rgba="0.792156862745098 0.819607843137255 0.933333333333333 1" />
	      </material>
	    </visual>
	    <collision>
	      <origin
		xyz="0 0 0"
		rpy="0 0 0" />
	      <geometry>
		<mesh
		  filename="package://single_arm_description/meshes/link_8.STL" />
	      </geometry>
	    </collision>
	  </link>
	  <joint
	    name="${side}joint_8"
	    type="revolute">
	    <origin
	      xyz="0 0 0.3985"
	      rpy="-1.5708 0 0" />
	    <parent
	      link="${side}link_7" />
	    <child
	      link="${side}link_8" />
	    <axis
	      xyz="0 0 -1" />
	    <limit
	      lower="-3.14"
	      upper="3.14"
	      effort="2"
	      velocity="2" />
	  </joint>
	-->
    <!-- <xacro:single_arm_transmission side="${side}" />
	  <xacro:single_arm_gazebo side="${side}" /> -->
    <link name="l_tool_link">
        <inertial>
            <origin rpy="0 0 0" xyz="-0.003041 0.0027723 0.043545" />
            <mass value="0.11123" />
            <inertia ixx="0.1" ixy="0.0" ixz="0.0" iyy="0.1" iyz="0.0" izz="0.1" />
        </inertial>
        <visual>
            <origin rpy="0 0 0" xyz="0 0 0" />
            <geometry>
                <mesh filename="package://suction_urdf/meshes/tool_link.STL" />
            </geometry>
            <material name="">
                <color rgba="1 1 1 1" />
            </material>
        </visual>
        <collision>
            <origin rpy="0 0 0" xyz="0 0 0" />
            <geometry>
                <mesh filename="package://suction_urdf/meshes/tool_link.STL" />
            </geometry>
        </collision>
    </link>
    <link name="l_tool_end_Link">
        <inertial>
            <origin rpy="0 0 0" xyz="9.909E-05 0.0039906 0.025651" />
            <mass value="0.033438" />
            <inertia ixx="0.1" ixy="0.0" ixz="0.0" iyy="0.1" iyz="0.0" izz="0.1" />
        </inertial>
        <visual>
            <origin rpy="0 0 0" xyz="0 0 0" />
            <geometry>
                <mesh filename="package://suction_urdf/meshes/tool_end_Link.STL" />
            </geometry>
            <material name="">
                <color rgba="0.79216 0.81961 0.93333 1" />
            </material>
        </visual>
        <collision>
            <origin rpy="0 0 0" xyz="0 0 0" />
            <geometry>
                <mesh filename="package://suction_urdf/meshes/tool_end_Link.STL" />
            </geometry>
        </collision>
    </link>
    <joint name="l_tool_joint" type="revolute">
        <origin rpy="-1.7985E-15 -2.9973E-16 1.1669E-16" xyz="0 0.002 0.1045" />
        <parent link="l_tool_link" />
        <child link="l_tool_end_Link" />
        <axis xyz="0 1 0" />
        <limit effort="1000" lower="-3.14" upper="3.14" velocity="6.5" />
        <dynamics damping="0.7" />
    </joint>
    <link name="l_end_Link1">
        <gravity>0</gravity>
        <inertial>
            <origin rpy="0 0 0" xyz="0 0 0" />
            <mass value="0.0001" />
            <inertia ixx="0.0001" ixy="0.000" ixz="0.000" iyy="0.0001" iyz="0.000" izz="0.0001" />
        </inertial>
        <visual>
            <origin rpy="0 0 0" xyz="0 0 0" />
            <geometry>
                <box size="0.01 0.01 0.01" />
            </geometry>
            <material name="transparent">
                <color rgba="0 0 0 0" />
            </material>
        </visual>
    </link>
    <joint name="l_end_joint1" type="revolute">
        <origin rpy="0 1.5708 0" xyz="0 -0.001 0.06" />
        <parent link="l_tool_end_Link" />
        <child link="l_end_Link1" />
        <axis xyz="1 0 0" />
        <limit effort="1000" lower="0" upper="0" velocity="6.5" />
        <dynamics damping="0.0" friction="10" />
    </joint>
    <link name="l_end_Link2">
        <gravity>0</gravity>
        <inertial>
            <origin rpy="0 0 0" xyz="0 0 0" />
            <mass value="0.0001" />
            <inertia ixx="0.0001" ixy="0.000" ixz="0.000" iyy="0.0001" iyz="0.000" izz="0.0001" />
        </inertial>
        <visual>
            <origin rpy="0 0 0" xyz="0 0 0" />
            <geometry>
                <box size="0.01 0.01 0.01" />
            </geometry>
            <material name="transparent">
                <color rgba="0 0 0 0" />
            </material>
        </visual>
    </link>
    <joint name="l_end_joint2" type="revolute">
        <origin rpy="0 1.5708 0" xyz="-0.0125 -0.001 0.06" />
        <parent link="l_tool_end_Link" />
        <child link="l_end_Link2" />
        <axis xyz="1 0 0" />
        <limit effort="1000" lower="0" upper="0" velocity="6.5" />
        <dynamics damping="0.0" friction="10" />
    </joint>
    <link name="l_end_Link3">
        <gravity>0</gravity>
        <inertial>
            <origin rpy="0 0 0" xyz="0 0 0" />
            <mass value="0.0001" />
            <inertia ixx="0.0001" ixy="0.000" ixz="0.000" iyy="0.0001" iyz="0.000" izz="0.0001" />
        </inertial>
        <visual>
            <origin rpy="0 0 0" xyz="0 0 0" />
            <geometry>
                <box size="0.01 0.01 0.01" />
            </geometry>
            <material name="transparent">
                <color rgba="0 0 0 0" />
            </material>
        </visual>
    </link>
    <joint name="l_end_joint3" type="revolute">
        <origin rpy="0 1.5708 0" xyz="0.0125 -0.001 0.06" />
        <parent link="l_tool_end_Link" />
        <child link="l_end_Link3" />
        <axis xyz="1 0 0" />
        <limit effort="1000" lower="0" upper="0" velocity="6.5" />
        <dynamics damping="0.0" friction="10" />
    </joint>
    <link name="l_end_Link4">
        <gravity>0</gravity>
        <inertial>
            <origin rpy="0 0 0" xyz="0 0 0" />
            <mass value="0.0001" />
            <inertia ixx="0.0001" ixy="0.000" ixz="0.000" iyy="0.0001" iyz="0.000" izz="0.0001" />
        </inertial>
        <visual>
            <origin rpy="0 0 0" xyz="0 0 0" />
            <geometry>
                <box size="0.01 0.01 0.01" />
            </geometry>
            <material name="transparent">
                <color rgba="0 0 0 0" />
            </material>
        </visual>
    </link>
    <joint name="l_end_joint4" type="revolute">
        <origin rpy="0 1.5708 0" xyz="0 -0.001 0.0475" />
        <parent link="l_tool_end_Link" />
        <child link="l_end_Link4" />
        <axis xyz="1 0 0" />
        <limit effort="1000" lower="0" upper="0" velocity="6.5" />
        <dynamics damping="0.0" friction="10" />
    </joint>
    <link name="l_end_Link5">
        <gravity>0</gravity>
        <inertial>
            <origin rpy="0 0 0" xyz="0 0 0" />
            <mass value="0.0001" />
            <inertia ixx="0.0001" ixy="0.000" ixz="0.000" iyy="0.0001" iyz="0.000" izz="0.0001" />
        </inertial>
        <visual>
            <origin rpy="0 0 0" xyz="0 0 0" />
            <geometry>
                <box size="0.01 0.01 0.01" />
            </geometry>
            <material name="transparent">
                <color rgba="0 0 0 0" />
            </material>
        </visual>
    </link>
    <joint name="l_end_joint5" type="revolute">
        <origin rpy="0 1.5708 0" xyz="0 -0.001 0.0725" />
        <parent link="l_tool_end_Link" />
        <child link="l_end_Link5" />
        <axis xyz="1 0 0" />
        <limit effort="1000" lower="0" upper="0" velocity="6.5" />
        <dynamics damping="0.0" friction="10" />
    </joint>
    <!-- <xacro:suction_transmission side="${side}" />
    <xacro:suction_gazebo side="${side}" /> -->
    <transmission name="trans_r_joint_1">
        <type>transmission_interface/SimpleTransmission</type>
        <joint name="r_joint_1">
            <hardwareInterface>hardware_interface/EffortJointInterface</hardwareInterface>
        </joint>
        <actuator name="r_joint_1_motor">
            <hardwareInterface>hardware_interface/EffortJointInterface</hardwareInterface>
            <mechanicalReduction>1</mechanicalReduction>
        </actuator>
    </transmission>
    <transmission name="trans_r_joint_2">
        <type>transmission_interface/SimpleTransmission</type>
        <joint name="r_joint_2">
            <hardwareInterface>hardware_interface/EffortJointInterface</hardwareInterface>
        </joint>
        <actuator name="r_joint_2_motor">
            <hardwareInterface>hardware_interface/EffortJointInterface</hardwareInterface>
            <mechanicalReduction>1</mechanicalReduction>
        </actuator>
    </transmission>
    <transmission name="trans_r_joint_3">
        <type>transmission_interface/SimpleTransmission</type>
        <joint name="r_joint_3">
            <hardwareInterface>hardware_interface/EffortJointInterface</hardwareInterface>
        </joint>
        <actuator name="r_joint_3_motor">
            <hardwareInterface>hardware_interface/EffortJointInterface</hardwareInterface>
            <mechanicalReduction>1</mechanicalReduction>
        </actuator>
    </transmission>
    <transmission name="trans_r_joint_4">
        <type>transmission_interface/SimpleTransmission</type>
        <joint name="r_joint_4">
            <hardwareInterface>hardware_interface/EffortJointInterface</hardwareInterface>
        </joint>
        <actuator name="r_joint_4_motor">
            <hardwareInterface>hardware_interface/EffortJointInterface</hardwareInterface>
            <mechanicalReduction>1</mechanicalReduction>
        </actuator>
    </transmission>
    <transmission name="trans_r_joint_5">
        <type>transmission_interface/SimpleTransmission</type>
        <joint name="r_joint_5">
            <hardwareInterface>hardware_interface/EffortJointInterface</hardwareInterface>
        </joint>
        <actuator name="r_joint_5_motor">
            <hardwareInterface>hardware_interface/EffortJointInterface</hardwareInterface>
            <mechanicalReduction>1</mechanicalReduction>
        </actuator>
    </transmission>
    <transmission name="trans_r_joint_6">
        <type>transmission_interface/SimpleTransmission</type>
        <joint name="r_joint_6">
            <hardwareInterface>hardware_interface/EffortJointInterface</hardwareInterface>
        </joint>
        <actuator name="r_joint_6_motor">
            <hardwareInterface>hardware_interface/EffortJointInterface</hardwareInterface>
            <mechanicalReduction>1</mechanicalReduction>
        </actuator>
    </transmission>
    <transmission name="trans_r_joint_7">
        <type>transmission_interface/SimpleTransmission</type>
        <joint name="r_joint_7">
            <hardwareInterface>hardware_interface/EffortJointInterface</hardwareInterface>
        </joint>
        <actuator name="r_joint_7_motor">
            <hardwareInterface>hardware_interface/EffortJointInterface</hardwareInterface>
            <mechanicalReduction>1</mechanicalReduction>
        </actuator>
    </transmission>
    <transmission name="trans_r_tool_joint">
        <type>transmission_interface/SimpleTransmission</type>
        <joint name="r_tool_joint">
            <hardwareInterface>hardware_interface/EffortJointInterface</hardwareInterface>
        </joint>
        <actuator name="r_tool_joint_motor">
            <hardwareInterface>hardware_interface/EffortJointInterface</hardwareInterface>
            <mechanicalReduction>1</mechanicalReduction>
        </actuator>
    </transmission>
    <transmission name="trans_r_end_joint1">
        <type>transmission_interface/SimpleTransmission</type>
        <joint name="r_end_joint1">
            <hardwareInterface>hardware_interface/EffortJointInterface</hardwareInterface>
        </joint>
        <actuator name="r_end_joint1_motor">
            <hardwareInterface>hardware_interface/EffortJointInterface</hardwareInterface>
            <mechanicalReduction>1</mechanicalReduction>
        </actuator>
    </transmission>
    <transmission name="trans_r_end_joint2">
        <type>transmission_interface/SimpleTransmission</type>
        <joint name="r_end_joint2">
            <hardwareInterface>hardware_interface/EffortJointInterface</hardwareInterface>
        </joint>
        <actuator name="r_end_joint2_motor">
            <hardwareInterface>hardware_interface/EffortJointInterface</hardwareInterface>
            <mechanicalReduction>1</mechanicalReduction>
        </actuator>
    </transmission>
    <transmission name="trans_r_end_joint3">
        <type>transmission_interface/SimpleTransmission</type>
        <joint name="r_end_joint3">
            <hardwareInterface>hardware_interface/EffortJointInterface</hardwareInterface>
        </joint>
        <actuator name="r_end_joint3_motor">
            <hardwareInterface>hardware_interface/EffortJointInterface</hardwareInterface>
            <mechanicalReduction>1</mechanicalReduction>
        </actuator>
    </transmission>
    <transmission name="trans_r_end_joint4">
        <type>transmission_interface/SimpleTransmission</type>
        <joint name="r_end_joint4">
            <hardwareInterface>hardware_interface/EffortJointInterface</hardwareInterface>
        </joint>
        <actuator name="r_end_joint4_motor">
            <hardwareInterface>hardware_interface/EffortJointInterface</hardwareInterface>
            <mechanicalReduction>1</mechanicalReduction>
        </actuator>
    </transmission>
    <transmission name="trans_r_end_joint5">
        <type>transmission_interface/SimpleTransmission</type>
        <joint name="r_end_joint5">
            <hardwareInterface>hardware_interface/EffortJointInterface</hardwareInterface>
        </joint>
        <actuator name="r_end_joint5_motor">
            <hardwareInterface>hardware_interface/EffortJointInterface</hardwareInterface>
            <mechanicalReduction>1</mechanicalReduction>
        </actuator>
    </transmission>
    <transmission name="trans_l_joint_1">
        <type>transmission_interface/SimpleTransmission</type>
        <joint name="l_joint_1">
            <hardwareInterface>hardware_interface/EffortJointInterface</hardwareInterface>
        </joint>
        <actuator name="l_joint_1_motor">
            <hardwareInterface>hardware_interface/EffortJointInterface</hardwareInterface>
            <mechanicalReduction>1</mechanicalReduction>
        </actuator>
    </transmission>
    <transmission name="trans_l_joint_2">
        <type>transmission_interface/SimpleTransmission</type>
        <joint name="l_joint_2">
            <hardwareInterface>hardware_interface/EffortJointInterface</hardwareInterface>
        </joint>
        <actuator name="l_joint_2_motor">
            <hardwareInterface>hardware_interface/EffortJointInterface</hardwareInterface>
            <mechanicalReduction>1</mechanicalReduction>
        </actuator>
    </transmission>
    <transmission name="trans_l_joint_3">
        <type>transmission_interface/SimpleTransmission</type>
        <joint name="l_joint_3">
            <hardwareInterface>hardware_interface/EffortJointInterface</hardwareInterface>
        </joint>
        <actuator name="l_joint_3_motor">
            <hardwareInterface>hardware_interface/EffortJointInterface</hardwareInterface>
            <mechanicalReduction>1</mechanicalReduction>
        </actuator>
    </transmission>
    <transmission name="trans_l_joint_4">
        <type>transmission_interface/SimpleTransmission</type>
        <joint name="l_joint_4">
            <hardwareInterface>hardware_interface/EffortJointInterface</hardwareInterface>
        </joint>
        <actuator name="l_joint_4_motor">
            <hardwareInterface>hardware_interface/EffortJointInterface</hardwareInterface>
            <mechanicalReduction>1</mechanicalReduction>
        </actuator>
    </transmission>
    <transmission name="trans_l_joint_5">
        <type>transmission_interface/SimpleTransmission</type>
        <joint name="l_joint_5">
            <hardwareInterface>hardware_interface/EffortJointInterface</hardwareInterface>
        </joint>
        <actuator name="l_joint_5_motor">
            <hardwareInterface>hardware_interface/EffortJointInterface</hardwareInterface>
            <mechanicalReduction>1</mechanicalReduction>
        </actuator>
    </transmission>
    <transmission name="trans_l_joint_6">
        <type>transmission_interface/SimpleTransmission</type>
        <joint name="l_joint_6">
            <hardwareInterface>hardware_interface/EffortJointInterface</hardwareInterface>
        </joint>
        <actuator name="l_joint_6_motor">
            <hardwareInterface>hardware_interface/EffortJointInterface</hardwareInterface>
            <mechanicalReduction>1</mechanicalReduction>
        </actuator>
    </transmission>
    <transmission name="trans_l_joint_7">
        <type>transmission_interface/SimpleTransmission</type>
        <joint name="l_joint_7">
            <hardwareInterface>hardware_interface/EffortJointInterface</hardwareInterface>
        </joint>
        <actuator name="l_joint_7_motor">
            <hardwareInterface>hardware_interface/EffortJointInterface</hardwareInterface>
            <mechanicalReduction>1</mechanicalReduction>
        </actuator>
    </transmission>
    <transmission name="trans_l_tool_joint">
        <type>transmission_interface/SimpleTransmission</type>
        <joint name="l_tool_joint">
            <hardwareInterface>hardware_interface/EffortJointInterface</hardwareInterface>
        </joint>
        <actuator name="l_tool_joint_motor">
            <hardwareInterface>hardware_interface/EffortJointInterface</hardwareInterface>
            <mechanicalReduction>1</mechanicalReduction>
        </actuator>
    </transmission>
    <transmission name="trans_l_end_joint1">
        <type>transmission_interface/SimpleTransmission</type>
        <joint name="l_end_joint1">
            <hardwareInterface>hardware_interface/EffortJointInterface</hardwareInterface>
        </joint>
        <actuator name="l_end_joint1_motor">
            <hardwareInterface>hardware_interface/EffortJointInterface</hardwareInterface>
            <mechanicalReduction>1</mechanicalReduction>
        </actuator>
    </transmission>
    <transmission name="trans_l_end_joint2">
        <type>transmission_interface/SimpleTransmission</type>
        <joint name="l_end_joint2">
            <hardwareInterface>hardware_interface/EffortJointInterface</hardwareInterface>
        </joint>
        <actuator name="l_end_joint2_motor">
            <hardwareInterface>hardware_interface/EffortJointInterface</hardwareInterface>
            <mechanicalReduction>1</mechanicalReduction>
        </actuator>
    </transmission>
    <transmission name="trans_l_end_joint3">
        <type>transmission_interface/SimpleTransmission</type>
        <joint name="l_end_joint3">
            <hardwareInterface>hardware_interface/EffortJointInterface</hardwareInterface>
        </joint>
        <actuator name="l_end_joint3_motor">
            <hardwareInterface>hardware_interface/EffortJointInterface</hardwareInterface>
            <mechanicalReduction>1</mechanicalReduction>
        </actuator>
    </transmission>
    <transmission name="trans_l_end_joint4">
        <type>transmission_interface/SimpleTransmission</type>
        <joint name="l_end_joint4">
            <hardwareInterface>hardware_interface/EffortJointInterface</hardwareInterface>
        </joint>
        <actuator name="l_end_joint4_motor">
            <hardwareInterface>hardware_interface/EffortJointInterface</hardwareInterface>
            <mechanicalReduction>1</mechanicalReduction>
        </actuator>
    </transmission>
    <transmission name="trans_l_end_joint5">
        <type>transmission_interface/SimpleTransmission</type>
        <joint name="l_end_joint5">
            <hardwareInterface>hardware_interface/EffortJointInterface</hardwareInterface>
        </joint>
        <actuator name="l_end_joint5_motor">
            <hardwareInterface>hardware_interface/EffortJointInterface</hardwareInterface>
            <mechanicalReduction>1</mechanicalReduction>
        </actuator>
    </transmission>
    <gazebo>
        <plugin name="gazebo_ros_control">
            <robotNamespace>/</robotNamespace>
        </plugin>
    </gazebo>
</robot>

