<?xml version="1.0"?>
<!-- This URDF was automatically created by SolidWorks to URDF Exporter! Originally created by Stephen Brawner (brawner@gmail.com) 
     Commit Version: 1.5.1-0-g916b5db  Build Version: 1.5.7152.31018
     For more information, please see http://wiki.ros.org/sw_urdf_exporter -->
<robot
  name="blue_arm" xmlns:xacro="http://www.ros.org/wiki/xacro">

  <xacro:arg name="use_nominal_extrinsics" default="true"/>
  <xacro:include filename="$(find realsense2_description)/urdf/_d405.urdf.xacro" />
  
  <xacro:sensor_d405 parent="link_7" use_nominal_extrinsics="$(arg use_nominal_extrinsics)">
    <origin xyz="0 0 0" rpy="0 0 0"/>
  </xacro:sensor_d405>
  
  <xacro:include filename="$(find blue_arm_description)/urdf/blue_arm.gazebo.xacro" />
  <xacro:include filename="$(find blue_arm_description)/urdf/blue_arm.transmission.xacro" />

  <link name="world"/>
  <joint name="joint_0 " type="fixed">
    <origin
      xyz="0 0 0"
      rpy="0 0 0" />
    <parent link="world"/>
    <child link="base_link"/>
  </joint>
  
  <link
    name="base_link">
    <inertial>
      <origin
        xyz="-1.2721E-09 -2.221E-09 0.029334"
        rpy="0 0 0" />
      <mass
        value="0.80823" />
      <inertia
        ixx="0.1"
        ixy="0"
        ixz="0"
        iyy="0.1"
        iyz="0"
        izz="0.1" />
    </inertial>
    <visual>
      <origin
        xyz="0 0 0"
        rpy="0 0 0" />
      <geometry>
        <mesh
          filename="package://blue_arm_description/meshes/visual/base_link.STL" />
      </geometry>
      <material
        name="">
        <color
          rgba="0.1 0.6 0.8 1" />
      </material>
    </visual>
    <collision>
      <origin
        xyz="0 0 0"
        rpy="0 0 0" />
      <geometry>
        <mesh
          filename="package://blue_arm_description/meshes/collision/base_link.STL" />
      </geometry>
    </collision>
  </link>
  <link
    name="link_1">
    <inertial>
      <origin
        xyz="0.0013724819847024 0.00105856120896306 -0.0137822751691176"
        rpy="0 0 0" />
      <mass
        value="0.842297822851205" />
      <inertia
        ixx="0.1"
        ixy="0"
        ixz="0"
        iyy="0.1"
        iyz="0"
        izz="0.1" />
    </inertial>
    <visual>
      <origin
        xyz="0 0 0"
        rpy="0 0 0" />
      <geometry>
        <mesh
          filename="package://blue_arm_description/meshes/visual/link_1.STL" />
      </geometry>
      <material
        name="">
        <color
          rgba="0.898039215686275 0.917647058823529 0.929411764705882 1" />
      </material>
    </visual>
    <collision>
      <origin
        xyz="0 0 0"
        rpy="0 0 0" />
      <geometry>
        <mesh
          filename="package://blue_arm_description/meshes/collision/link_1.STL" />
      </geometry>
    </collision>
  </link>
  <joint
    name="joint_1"
    type="revolute">
    <origin
      xyz="0 0 0.14"
      rpy="0 0 0" />
    <parent
      link="base_link" />
    <child
      link="link_1" />
    <axis
      xyz="0 0 1" />
    <limit
      lower="-3.1415926"
      upper="3.1415926"
      effort="1200"
      velocity="3.29" />
  </joint>
  <link
    name="link_2">
    <inertial>
      <origin
        xyz="0.0769223200130146 8.08732473817575E-05 -0.00042635625580266"
        rpy="0 0 0" />
      <mass
        value="0.745981126447571" />
      <inertia
        ixx="0.1"
        ixy="0"
        ixz="0"
        iyy="0.1"
        iyz="0"
        izz="0.1" />
    </inertial>
    <visual>
      <origin
        xyz="0 0 0"
        rpy="0 0 0" />
      <geometry>
        <mesh
          filename="package://blue_arm_description/meshes/visual/link_2.STL" />
      </geometry>
      <material
        name="">
        <color
          rgba="0.1 0.6 0.8 1" />
      </material>
    </visual>
    <collision>
      <origin
        xyz="0 0 0"
        rpy="0 0 0" />
      <geometry>
        <mesh
          filename="package://blue_arm_description/meshes/collision/link_2.STL" />
      </geometry>
    </collision>
  </link>
  <joint
    name="joint_2"
    type="revolute">
    <origin
      xyz="0 0 0"
      rpy="0 0 0" />
    <parent
      link="link_1" />
    <child
      link="link_2" />
    <axis
      xyz="0 1 0" />
    <limit
      lower="-3.1415926"
      upper="0"
      effort="1200"
      velocity="3.29" />
  </joint>
  <link
    name="link_3">
    <inertial>
      <origin
        xyz="-0.0114331813251084 -0.000457582008541844 -0.0216566472730735"
        rpy="0 0 0" />
      <mass
        value="0.804459827803754" />
      <inertia
        ixx="0.1"
        ixy="0"
        ixz="0"
        iyy="0.1"
        iyz="0"
        izz="0.1" />
    </inertial>
    <visual>
      <origin
        xyz="0 0 0"
        rpy="0 0 0" />
      <geometry>
        <mesh
          filename="package://blue_arm_description/meshes/visual/link_3.STL" />
      </geometry>
      <material
        name="">
        <color
          rgba="0.898039215686275 0.917647058823529 0.929411764705882 1" />
      </material>
    </visual>
    <collision>
      <origin
        xyz="0 0 0"
        rpy="0 0 0" />
      <geometry>
        <mesh
          filename="package://blue_arm_description/meshes/collision/link_3.STL" />
      </geometry>
    </collision>
  </link>
  <joint
    name="joint_3"
    type="revolute">
    <origin
      xyz="0.1415 0 0"
      rpy="0 0 0" />
    <parent
      link="link_2" />
    <child
      link="link_3" />
    <axis
      xyz="1 0 0" />
    <limit
      lower="-3.1415926"
      upper="3.1415926"
      effort="1000"
      velocity="2.39" />
  </joint>
  <link
    name="link_4">
    <inertial>
      <origin
        xyz="0.0769734778463645 0.000934629244450365 0.0356212264841299"
        rpy="0 0 0" />
      <mass
        value="0.566230423072006" />
      <inertia
        ixx="0.1"
        ixy="0"
        ixz="0"
        iyy="0.1"
        iyz="0"
        izz="0.1" />
    </inertial>
    <visual>
      <origin
        xyz="0 0 0"
        rpy="0 0 0" />
      <geometry>
        <mesh
          filename="package://blue_arm_description/meshes/visual/link_4.STL" />
      </geometry>
      <material
        name="">
        <color
          rgba="0.1 0.6 0.8 1" />
      </material>
    </visual>
    <collision>
      <origin
        xyz="0 0 0"
        rpy="0 0 0" />
      <geometry>
        <mesh
          filename="package://blue_arm_description/meshes/collision/link_4.STL" />
      </geometry>
    </collision>
  </link>
  <joint
    name="joint_4"
    type="revolute">
    <origin
      xyz="0.0485 0 -0.0365"
      rpy="0 0 0" />
    <parent
      link="link_3" />
    <child
      link="link_4" />
    <axis
      xyz="0 -1 0" />
    <limit
      lower="-3.1415926"
      upper="0"
      effort="1000"
      velocity="2.39" />
  </joint>
  <link
    name="link_5">
    <inertial>
      <origin
        xyz="-0.0148074583751761 0.00213542128687548 2.18169794868883E-07"
        rpy="0 0 0" />
      <mass
        value="0.462017126683371" />
      <inertia
        ixx="0.1"
        ixy="0"
        ixz="0"
        iyy="0.1"
        iyz="0"
        izz="0.1" />
    </inertial>
    <visual>
      <origin
        xyz="0 0 0"
        rpy="0 0 0" />
      <geometry>
        <mesh
          filename="package://blue_arm_description/meshes/visual/link_5.STL" />
      </geometry>
      <material
        name="">
        <color
          rgba="0.898039215686275 0.917647058823529 0.929411764705882 1" />
      </material>
    </visual>
    <collision>
      <origin
        xyz="0 0 0"
        rpy="0 0 0" />
      <geometry>
        <mesh
          filename="package://blue_arm_description/meshes/collision/link_5.STL" />
      </geometry>
    </collision>
  </link>
  <joint
    name="joint_5"
    type="revolute">
    <origin
      xyz="0.183 0 0.0365"
      rpy="0 0 0" />
    <parent
      link="link_4" />
    <child
      link="link_5" />
    <axis
      xyz="1 0 0" />
    <limit
      lower="-3.1415926"
      upper="3.1415926"
      effort="1000"
      velocity="2.39" />
  </joint>
  <link
    name="link_6">
    <inertial>
      <origin
        xyz="0.057311 -0.0040732 2.7725E-07"
        rpy="0 0 0" />
      <mass
        value="0.41677" />
      <inertia
        ixx="0.1"
        ixy="0"
        ixz="0"
        iyy="0.1"
        iyz="0"
        izz="0.1" />
    </inertial>
    <visual>
      <origin
        xyz="0 0 0"
        rpy="0 0 0" />
      <geometry>
        <mesh
          filename="package://blue_arm_description/meshes/visual/link_6.STL" />
      </geometry>
      <material
        name="">
        <color
          rgba="0.1 0.6 0.8 1" />
      </material>
    </visual>
    <collision>
      <origin
        xyz="0 0 0"
        rpy="0 0 0" />
      <geometry>
        <mesh
          filename="package://blue_arm_description/meshes/collision/link_6.STL" />
      </geometry>
    </collision>
  </link>
  <joint
    name="joint_6"
    type="revolute">
    <origin
      xyz="0 0 0"
      rpy="0 0 0" />
    <parent
      link="link_5" />
    <child
      link="link_6" />
    <axis
      xyz="0 -1 0" />
    <limit
      lower="-1.7"
      upper="1.7"
      effort="1000"
      velocity="2.77" />
  </joint>
  <link
    name="link_7">
    <inertial>
      <origin
        xyz="0 0 0"
        rpy="0 0 0" />
      <mass
        value="0.1" />
      <inertia
        ixx="0.1"
        ixy="0"
        ixz="0"
        iyy="0.1"
        iyz="0"
        izz="0.1" />
    </inertial>
    <collision>
      <geometry>
        <box size="0.01 0.01 0.01"/>
      </geometry>
      <origin rpy="0 0 0" xyz="0 0 0"/>
    </collision>
  </link>
  <joint
    name="joint_7"
    type="revolute">
    <origin
      xyz="0.107 0 0"
      rpy="0 0 0" />
    <parent
      link="link_6" />
    <child
      link="link_7" />
    <axis
      xyz="1 0 0" />
    <limit
      lower="-3.1415926"
      upper="3.1415926"
      effort="1000"
      velocity="2.77" />
  </joint>
</robot>