<?xml version="1.0"?>
<!-- This URDF was automatically created by SolidWorks to URDF Exporter! Originally created by Stephen Brawner (brawner@gmail.com) 
     Commit Version: 1.5.1-0-g916b5db  Build Version: 1.5.7152.31018
     For more information, please see http://wiki.ros.org/sw_urdf_exporter -->
<robot
  name="blue_arm" xmlns:xacro="http://www.ros.org/wiki/xacro">
  
  <xacro:include filename="$(find blue_arm_description)/urdf/blue_arm.gazebo.xacro" />
  <xacro:include filename="$(find blue_arm_description)/urdf/blue_arm.transmission.xacro" />

  <link name="world"/>
  <joint name="joint_0 " type="fixed">
    <origin
      xyz="0 0 0"
      rpy="0 0 0" />
    <parent link="world"/>
    <child link="base_link"/>
  </joint>
  
  <link
    name="base_link">
    <inertial>
      <origin
        xyz="-1.2721E-09 -2.221E-09 0.029334"
        rpy="0 0 0" />
      <mass
        value="0.80823" />
      <inertia
        ixx="0.00092021"
        ixy="2.0871E-10"
        ixz="-1.3863E-11"
        iyy="0.00088788"
        iyz="-1.2165E-11"
        izz="0.001593" />
    </inertial>
    <visual>
      <origin
        xyz="0 0 0"
        rpy="0 0 0" />
      <geometry>
        <mesh
          filename="package://blue_arm_description/meshes/base_link.STL" />
      </geometry>
      <material
        name="">
        <color
          rgba="0.50196 1 1 1" />
      </material>
    </visual>
    <collision>
      <origin
        xyz="0 0 0"
        rpy="0 0 0" />
      <geometry>
        <mesh
          filename="package://blue_arm_description/meshes/base_link.STL" />
      </geometry>
    </collision>
  </link>
  <link
    name="link_1">
    <inertial>
      <origin
        xyz="0.0013725 -0.013782 -0.0010586"
        rpy="0 0 0" />
      <mass
        value="0.8423" />
      <inertia
        ixx="0.00076341"
        ixy="-3.9598E-06"
        ixz="3.5164E-06"
        iyy="0.0010223"
        iyz="-1.3672E-06"
        izz="0.0012198" />
    </inertial>
    <visual>
      <origin
        xyz="0 0 0"
        rpy="0 0 0" />
      <geometry>
        <mesh
          filename="package://blue_arm_description/meshes/link_1.STL" />
      </geometry>
      <material
        name="">
        <color
          rgba="0.89804 0.91765 0.92941 1" />
      </material>
    </visual>
    <collision>
      <origin
        xyz="0 0 0"
        rpy="0 0 0" />
      <geometry>
        <mesh
          filename="package://blue_arm_description/meshes/link_1.STL" />
      </geometry>
    </collision>
  </link>
  <joint
    name="joint_1"
    type="revolute">
    <origin
      xyz="0 0 0.14"
      rpy="1.5708 0 0" />
    <parent
      link="base_link" />
    <child
      link="link_1" />
    <axis
      xyz="0 1 0" />
    <limit
      lower="-3.1415926"
      upper="3.1415926"
      effort="1000"
      velocity="6" />
  </joint>
  <link
    name="link_2">
    <inertial>
      <origin
        xyz="-0.00042855 0.00012029 0.077319"
        rpy="0 0 0" />
      <mass
        value="0.74215" />
      <inertia
        ixx="0.00038342"
        ixy="5.5202E-06"
        ixz="-1.9563E-06"
        iyy="0.00042263"
        iyz="4.8133E-06"
        izz="0.00051977" />
    </inertial>
    <visual>
      <origin
        xyz="0 0 0"
        rpy="0 0 0" />
      <geometry>
        <mesh
          filename="package://blue_arm_description/meshes/link_2.STL" />
      </geometry>
      <material
        name="">
        <color
          rgba="0.89804 0.91765 0.92941 1" />
      </material>
    </visual>
    <collision>
      <origin
        xyz="0 0 0"
        rpy="0 0 0" />
      <geometry>
        <mesh
          filename="package://blue_arm_description/meshes/link_2.STL" />
      </geometry>
    </collision>
  </link>
  <joint
    name="joint_2"
    type="revolute">
    <origin
      xyz="0 0 0"
      rpy="1.5708 0 1.5708" />
    <parent
      link="link_1" />
    <child
      link="link_2" />
    <axis
      xyz="0 1 0" />
    <limit
      lower="-3.1415926"
      upper="3.1415926"
      effort="1000"
      velocity="6" />
  </joint>
  <link
    name="link_3">
    <inertial>
      <origin
        xyz="-0.014843 -0.011433 0.00045758"
        rpy="0 0 0" />
      <mass
        value="0.80446" />
      <inertia
        ixx="0.00033529"
        ixy="1.1516E-05"
        ixz="-1.522E-06"
        iyy="0.00039472"
        iyz="-1.2003E-06"
        izz="0.00036918" />
    </inertial>
    <visual>
      <origin
        xyz="0 0 0"
        rpy="0 0 0" />
      <geometry>
        <mesh
          filename="package://blue_arm_description/meshes/link_3.STL" />
      </geometry>
      <material
        name="">
        <color
          rgba="0.89804 0.91765 0.92941 1" />
      </material>
    </visual>
    <collision>
      <origin
        xyz="0 0 0"
        rpy="0 0 0" />
      <geometry>
        <mesh
          filename="package://blue_arm_description/meshes/link_3.STL" />
      </geometry>
    </collision>
  </link>
  <joint
    name="joint_3"
    type="revolute">
    <origin
      xyz="-0.0365 0 0.19"
      rpy="1.5708 0 3.1416" />
    <parent
      link="link_2" />
    <child
      link="link_3" />
    <axis
      xyz="0 -1 0" />
    <limit
      lower="-3.1415926"
      upper="3.1415926"
      effort="1000"
      velocity="6" />
  </joint>
  <link
    name="link_4">
    <inertial>
      <origin
        xyz="-0.00072048 -0.00077504 0.077316"
        rpy="0 0 0" />
      <mass
        value="0.56373" />
      <inertia
        ixx="0.00022143"
        ixy="6.1006E-06"
        ixz="-1.1814E-05"
        iyy="0.00022511"
        iyz="-1.2919E-06"
        izz="0.00032324" />
    </inertial>
    <visual>
      <origin
        xyz="0 0 0"
        rpy="0 0 0" />
      <geometry>
        <mesh
          filename="package://blue_arm_description/meshes/link_4.STL" />
      </geometry>
      <material
        name="">
        <color
          rgba="0.89804 0.91765 0.92941 1" />
      </material>
    </visual>
    <collision>
      <origin
        xyz="0 0 0"
        rpy="0 0 0" />
      <geometry>
        <mesh
          filename="package://blue_arm_description/meshes/link_4.STL" />
      </geometry>
    </collision>
  </link>
  <joint
    name="joint_4"
    type="revolute">
    <origin
      xyz="-0.0365 0 0"
      rpy="1.5708 0 3.1416" />
    <parent
      link="link_3" />
    <child
      link="link_4" />
    <axis
      xyz="0 -1 0" />
    <limit
      lower="-3.1415926"
      upper="3.1415926"
      effort="1000"
      velocity="6" />
  </joint>
  <link
    name="link_5">
    <inertial>
      <origin
        xyz="-2.1511E-07 -0.0146 -0.0025524"
        rpy="0 0 0" />
      <mass
        value="0.4686" />
      <inertia
        ixx="0.00016349"
        ixy="3.0569E-07"
        ixz="1.1246E-09"
        iyy="0.00017827"
        iyz="-1.3267E-05"
        izz="0.0002263" />
    </inertial>
    <visual>
      <origin
        xyz="0 0 0"
        rpy="0 0 0" />
      <geometry>
        <mesh
          filename="package://blue_arm_description/meshes/link_5.STL" />
      </geometry>
      <material
        name="">
        <color
          rgba="0.89804 0.91765 0.92941 1" />
      </material>
    </visual>
    <collision>
      <origin
        xyz="0 0 0"
        rpy="0 0 0" />
      <geometry>
        <mesh
          filename="package://blue_arm_description/meshes/link_5.STL" />
      </geometry>
    </collision>
  </link>
  <joint
    name="joint_5"
    type="revolute">
    <origin
      xyz="0 0 0.183"
      rpy="1.5708 0 -3.1416" />
    <parent
      link="link_4" />
    <child
      link="link_5" />
    <axis
      xyz="0 -1 0" />
    <limit
      lower="-3.1415926"
      upper="3.1415926"
      effort="1000"
      velocity="6" />
  </joint>
  <link
    name="link_6">
    <inertial>
      <origin
        xyz="2.817E-07 0.0046492 0.058231"
        rpy="0 0 0" />
      <mass
        value="0.41019" />
      <inertia
        ixx="0.00014763"
        ixy="3.057E-07"
        ixz="-1.3757E-09"
        iyy="0.00010609"
        iyz="1.4409E-05"
        izz="0.00018809" />
    </inertial>
    <visual>
      <origin
        xyz="0 0 0"
        rpy="0 0 0" />
      <geometry>
        <mesh
          filename="package://blue_arm_description/meshes/link_6.STL" />
      </geometry>
      <material
        name="">
        <color
          rgba="0.89804 0.91765 0.92941 1" />
      </material>
    </visual>
    <collision>
      <origin
        xyz="0 0 0"
        rpy="0 0 0" />
      <geometry>
        <mesh
          filename="package://blue_arm_description/meshes/link_6.STL" />
      </geometry>
    </collision>
  </link>
  <joint
    name="joint_6"
    type="revolute">
    <origin
      xyz="0 0 0"
      rpy="1.5708 0 -3.1416" />
    <parent
      link="link_5" />
    <child
      link="link_6" />
    <axis
      xyz="0 -1 0" />
    <limit
      lower="-3.1415926"
      upper="3.1415926"
      effort="1000"
      velocity="6" />
  </joint>
  <link
    name="link_7">
    <inertial>
      <origin
        xyz="0 0 0"
        rpy="0 0 0" />
      <mass
        value="0.1" />
      <inertia
        ixx="0.01"
        ixy="0"
        ixz="0"
        iyy="0.01"
        iyz="0"
        izz="0.01" />
    </inertial>
    <collision>
      <geometry>
        <box size="0.01 0.01 0.01"/>
      </geometry>
      <origin rpy="0 0 0" xyz="0 0 0"/>
    </collision>
  </link>
  <!-- <link
    name="link_7">
    <inertial>
      <origin
        xyz="-0.35508 -0.0025946 -0.026841"
        rpy="0 0 0" />
      <mass
        value="6.3956" />
      <inertia
        ixx="0.01645"
        ixy="-0.0011027"
        ixz="-0.017005"
        iyy="0.15129"
        iyz="0.00032406"
        izz="0.14249" />
    </inertial>
    <visual>
      <origin
        xyz="0 0 0"
        rpy="0 0 0" />
      <geometry>
        <mesh
          filename="package://blue_arm_description/meshes/link_7.STL" />
      </geometry>
      <material
        name="">
        <color
          rgba="1 1 1 1" />
      </material>
    </visual>
    <collision>
      <origin
        xyz="0 0 0"
        rpy="0 0 0" />
      <geometry>
        <mesh
          filename="package://blue_arm_description/meshes/link_7.STL" />
      </geometry>
    </collision>
  </link> -->
  <joint
    name="joint_7"
    type="revolute">
    <origin
      xyz="0 0 0.107"
      rpy="0 -1.5708 0" />
    <parent
      link="link_6" />
    <child
      link="link_7" />
    <axis
      xyz="-1 0 0" />
    <limit
      lower="-3.1415926"
      upper="3.1415926"
      effort="1000"
      velocity="6" />
  </joint>
</robot>