<?xml version="1.0" ?>
<!-- =================================================================================== -->
<!-- |    This document was autogenerated by xacro from /home/iclab/work/src/robot_models/ur_description/urdf/ur5e_cam.urdf.xacro | -->
<!-- |    EDITING THIS FILE BY HAND IS NOT RECOMMENDED                                 | -->
<!-- =================================================================================== -->
<robot name="ur5e">
    <!--
    Base UR robot series xacro macro.

    NOTE this is NOT a URDF. It cannot directly be loaded by consumers
    expecting a flattened '.urdf' file. See the top-level '.xacro' for that
    (but note that .xacro must still be processed by the xacro command).

    This file models the base kinematic chain of a UR robot, which then gets
    parameterised by various configuration files to convert it into a UR3(e),
    UR5(e), UR10(e) or UR16e.

    NOTE the default kinematic parameters (i.e., link lengths, frame locations,
    offsets, etc) do not correspond to any particular robot. They are defaults
    only. There WILL be non-zero offsets between the Forward Kinematics results
    in TF (i.e., robot_state_publisher) and the values reported by the Teach
    Pendant.

    For accurate (and robot-specific) transforms, the 'kinematics_parameters_file'
    parameter MUST point to a .yaml file containing the appropriate values for
    the targeted robot.

    If using the UniversalRobots/Universal_Robots_ROS_Driver, follow the steps
    described in the readme of that repository to extract the kinematic
    calibration from the controller and generate the required .yaml file.

    Main author of the migration to yaml configs Ludovic Delval.

    Contributors to previous versions (in no particular order)

     - Denis Stogl
     - Lovro Ivanov
     - Felix Messmer
     - Kelsey Hawkins
     - Wim Meeussen
     - Shaun Edwards
     - Nadia Hammoudeh Garcia
     - Dave Hershberger
     - G. vd. Hoorn
     - Philip Long
     - Dave Coleman
     - Miguel Prada
     - Mathias Luedtke
     - Marcel Schnirring
     - Felix von Drigalski
     - Felix Exner
     - Jimmy Da Silva
     - Ajit Krisshna N L
     - Muhammad Asif Rana
  -->
    <!--
    NOTE the macro defined in this file is NOT part of the public API of this
          package. Users CANNOT rely on this file being available, or stored in
          this location. Nor can they rely on the existence of the macro.
  -->
    <!-- create link fixed to the "world" -->
    <link name="world" />
    <ros2_control name="ur" type="system">
        <hardware>
            <plugin>ur_robot_driver/URPositionHardwareInterface</plugin>
            <param name="robot_ip">0.0.0.0</param>
            <param name="script_filename" />
            <param name="output_recipe_filename" />
            <param name="input_recipe_filename" />
            <param name="headless_mode">False</param>
            <param name="reverse_port">50001</param>
            <param name="script_sender_port">50002</param>
            <param name="reverse_ip">0.0.0.0</param>
            <param name="script_command_port">50004</param>
            <param name="trajectory_port">50003</param>
            <param name="tf_prefix" />
            <param name="non_blocking_read">True</param>
            <param name="servoj_gain">2000</param>
            <param name="servoj_lookahead_time">0.03</param>
            <param name="use_tool_communication">False</param>
            <param name="kinematics/hash">calib_12788084448423163542</param>
            <param name="tool_voltage">0</param>
            <param name="tool_parity">0</param>
            <param name="tool_baud_rate">115200</param>
            <param name="tool_stop_bits">1</param>
            <param name="tool_rx_idle_chars">1.5</param>
            <param name="tool_tx_idle_chars">3.5</param>
            <param name="tool_device_name">/tmp/ttyUR</param>
            <param name="tool_tcp_port">54321</param>
            <param name="keep_alive_count">2</param>
        </hardware>
        <joint name="shoulder_pan_joint">
            <command_interface name="position">
                <param name="min">{-2*pi}</param>
                <param name="max">{2*pi}</param>
            </command_interface>
            <command_interface name="velocity">
                <param name="min">-3.15</param>
                <param name="max">3.15</param>
            </command_interface>
            <state_interface name="position">
                <!-- initial position for the FakeSystem and simulation -->
                <param name="initial_value">0.0</param>
            </state_interface>
            <state_interface name="velocity" />
            <state_interface name="effort" />
        </joint>
        <joint name="shoulder_lift_joint">
            <command_interface name="position">
                <param name="min">{-2*pi}</param>
                <param name="max">{2*pi}</param>
            </command_interface>
            <command_interface name="velocity">
                <param name="min">-3.15</param>
                <param name="max">3.15</param>
            </command_interface>
            <state_interface name="position">
                <!-- initial position for the FakeSystem and simulation -->
                <param name="initial_value">-1.57</param>
            </state_interface>
            <state_interface name="velocity" />
            <state_interface name="effort" />
        </joint>
        <joint name="elbow_joint">
            <command_interface name="position">
                <param name="min">{-pi}</param>
                <param name="max">{pi}</param>
            </command_interface>
            <command_interface name="velocity">
                <param name="min">-3.15</param>
                <param name="max">3.15</param>
            </command_interface>
            <state_interface name="position">
                <!-- initial position for the FakeSystem and simulation -->
                <param name="initial_value">0.0</param>
            </state_interface>
            <state_interface name="velocity" />
            <state_interface name="effort" />
        </joint>
        <joint name="wrist_1_joint">
            <command_interface name="position">
                <param name="min">{-2*pi}</param>
                <param name="max">{2*pi}</param>
            </command_interface>
            <command_interface name="velocity">
                <param name="min">-3.2</param>
                <param name="max">3.2</param>
            </command_interface>
            <state_interface name="position">
                <!-- initial position for the FakeSystem and simulation -->
                <param name="initial_value">-1.57</param>
            </state_interface>
            <state_interface name="velocity" />
            <state_interface name="effort" />
        </joint>
        <joint name="wrist_2_joint">
            <command_interface name="position">
                <param name="min">{-2*pi}</param>
                <param name="max">{2*pi}</param>
            </command_interface>
            <command_interface name="velocity">
                <param name="min">-3.2</param>
                <param name="max">3.2</param>
            </command_interface>
            <state_interface name="position">
                <!-- initial position for the FakeSystem and simulation -->
                <param name="initial_value">0.0</param>
            </state_interface>
            <state_interface name="velocity" />
            <state_interface name="effort" />
        </joint>
        <joint name="wrist_3_joint">
            <command_interface name="position">
                <param name="min">{-2*pi}</param>
                <param name="max">{2*pi}</param>
            </command_interface>
            <command_interface name="velocity">
                <param name="min">-3.2</param>
                <param name="max">3.2</param>
            </command_interface>
            <state_interface name="position">
                <!-- initial position for the FakeSystem and simulation -->
                <param name="initial_value">0.0</param>
            </state_interface>
            <state_interface name="velocity" />
            <state_interface name="effort" />
        </joint>
        <sensor name="tcp_fts_sensor">
            <state_interface name="force.x" />
            <state_interface name="force.y" />
            <state_interface name="force.z" />
            <state_interface name="torque.x" />
            <state_interface name="torque.y" />
            <state_interface name="torque.z" />
        </sensor>
        <!-- NOTE The following are joints used only for testing with fake hardware and will change in the future -->
        <gpio name="speed_scaling">
            <state_interface name="speed_scaling_factor" />
            <param name="initial_speed_scaling_factor">1</param>
            <command_interface name="target_speed_fraction_cmd" />
            <command_interface name="target_speed_fraction_async_success" />
        </gpio>
        <gpio name="gpio">
            <command_interface name="standard_digital_output_cmd_0" />
            <command_interface name="standard_digital_output_cmd_1" />
            <command_interface name="standard_digital_output_cmd_2" />
            <command_interface name="standard_digital_output_cmd_3" />
            <command_interface name="standard_digital_output_cmd_4" />
            <command_interface name="standard_digital_output_cmd_5" />
            <command_interface name="standard_digital_output_cmd_6" />
            <command_interface name="standard_digital_output_cmd_7" />
            <command_interface name="standard_digital_output_cmd_8" />
            <command_interface name="standard_digital_output_cmd_9" />
            <command_interface name="standard_digital_output_cmd_10" />
            <command_interface name="standard_digital_output_cmd_11" />
            <command_interface name="standard_digital_output_cmd_12" />
            <command_interface name="standard_digital_output_cmd_13" />
            <command_interface name="standard_digital_output_cmd_14" />
            <command_interface name="standard_digital_output_cmd_15" />
            <command_interface name="standard_digital_output_cmd_16" />
            <command_interface name="standard_digital_output_cmd_17" />
            <command_interface name="standard_analog_output_cmd_0" />
            <command_interface name="standard_analog_output_cmd_1" />
            <command_interface name="tool_voltage_cmd" />
            <command_interface name="io_async_success" />
            <state_interface name="digital_output_0" />
            <state_interface name="digital_output_1" />
            <state_interface name="digital_output_2" />
            <state_interface name="digital_output_3" />
            <state_interface name="digital_output_4" />
            <state_interface name="digital_output_5" />
            <state_interface name="digital_output_6" />
            <state_interface name="digital_output_7" />
            <state_interface name="digital_output_8" />
            <state_interface name="digital_output_9" />
            <state_interface name="digital_output_10" />
            <state_interface name="digital_output_11" />
            <state_interface name="digital_output_12" />
            <state_interface name="digital_output_13" />
            <state_interface name="digital_output_14" />
            <state_interface name="digital_output_15" />
            <state_interface name="digital_output_16" />
            <state_interface name="digital_output_17" />
            <state_interface name="digital_input_0" />
            <state_interface name="digital_input_1" />
            <state_interface name="digital_input_2" />
            <state_interface name="digital_input_3" />
            <state_interface name="digital_input_4" />
            <state_interface name="digital_input_5" />
            <state_interface name="digital_input_6" />
            <state_interface name="digital_input_7" />
            <state_interface name="digital_input_8" />
            <state_interface name="digital_input_9" />
            <state_interface name="digital_input_10" />
            <state_interface name="digital_input_11" />
            <state_interface name="digital_input_12" />
            <state_interface name="digital_input_13" />
            <state_interface name="digital_input_14" />
            <state_interface name="digital_input_15" />
            <state_interface name="digital_input_16" />
            <state_interface name="digital_input_17" />
            <state_interface name="standard_analog_output_0" />
            <state_interface name="standard_analog_output_1" />
            <state_interface name="standard_analog_input_0" />
            <state_interface name="standard_analog_input_1" />
            <state_interface name="analog_io_type_0" />
            <state_interface name="analog_io_type_1" />
            <state_interface name="analog_io_type_2" />
            <state_interface name="analog_io_type_3" />
            <state_interface name="tool_mode" />
            <state_interface name="tool_output_voltage" />
            <state_interface name="tool_output_current" />
            <state_interface name="tool_temperature" />
            <state_interface name="tool_analog_input_0" />
            <state_interface name="tool_analog_input_1" />
            <state_interface name="tool_analog_input_type_0" />
            <state_interface name="tool_analog_input_type_1" />
            <state_interface name="robot_mode" />
            <state_interface name="robot_status_bit_0" />
            <state_interface name="robot_status_bit_1" />
            <state_interface name="robot_status_bit_2" />
            <state_interface name="robot_status_bit_3" />
            <state_interface name="safety_mode" />
            <state_interface name="safety_status_bit_0" />
            <state_interface name="safety_status_bit_1" />
            <state_interface name="safety_status_bit_2" />
            <state_interface name="safety_status_bit_3" />
            <state_interface name="safety_status_bit_4" />
            <state_interface name="safety_status_bit_5" />
            <state_interface name="safety_status_bit_6" />
            <state_interface name="safety_status_bit_7" />
            <state_interface name="safety_status_bit_8" />
            <state_interface name="safety_status_bit_9" />
            <state_interface name="safety_status_bit_10" />
            <state_interface name="program_running" />
        </gpio>
        <gpio name="payload">
            <command_interface name="mass" />
            <command_interface name="cog.x" />
            <command_interface name="cog.y" />
            <command_interface name="cog.z" />
            <command_interface name="payload_async_success" />
        </gpio>
        <gpio name="resend_robot_program">
            <command_interface name="resend_robot_program_cmd" />
            <command_interface name="resend_robot_program_async_success" />
        </gpio>
        <gpio name="hand_back_control">
            <command_interface name="hand_back_control_cmd" />
            <command_interface name="hand_back_control_async_success" />
        </gpio>
        <gpio name="zero_ftsensor">
            <command_interface name="zero_ftsensor_cmd" />
            <command_interface name="zero_ftsensor_async_success" />
        </gpio>
        <gpio name="system_interface">
            <state_interface name="initialized" />
        </gpio>
    </ros2_control>
    <!-- Add URDF transmission elements (for ros_control) -->
    <!--<xacro:ur_arm_transmission prefix="${prefix}" hw_interface="${transmission_hw_interface}" />-->
    <!-- Placeholder for ros2_control transmission which don't yet exist -->
    <!-- links -  main serial chain -->
    <link name="base_link" />
    <!-- <link name="${tf_prefix}base_link_inertia">
      <visual>
        <origin xyz="0 0 0" rpy="0 0 ${pi}"/>
        <geometry>
          <xacro:get_mesh name="base" type="visual"/>
        </geometry>
      </visual>
      <collision>
        <origin xyz="0 0 0" rpy="0 0 ${pi}"/>
        <geometry>
          <xacro:get_mesh name="base" type="collision"/>
        </geometry>
      </collision>
      <xacro:cylinder_inertial radius="${base_inertia_radius}" length="${base_inertia_length}" mass="${base_mass}">
        <origin xyz="0 0 0" rpy="0 0 0" />
      </xacro:cylinder_inertial>
    </link> -->
    <link name="shoulder_link">
        <visual>
            <origin rpy="0 0 3.141592653589793" xyz="0 0 0" />
            <geometry>
                <mesh filename="package://ur_description/meshes/ur5e/visual/shoulder.dae" />
            </geometry>
        </visual>
        <collision>
            <origin rpy="0 0 3.141592653589793" xyz="0 0 0" />
            <geometry>
                <mesh filename="package://ur_description/meshes/ur5e/collision/shoulder.stl" />
            </geometry>
        </collision>
        <inertial>
            <mass value="3.7" />
            <origin rpy="0 0 0" xyz="0 0 0" />
            <inertia ixx="0.010267495893" ixy="0.0" ixz="0.0" iyy="0.010267495893" iyz="0.0" izz="0.00666" />
        </inertial>
    </link>
    <link name="upper_arm_link">
        <visual>
            <origin rpy="1.5707963267948966 0 -1.5707963267948966" xyz="0 0 0.138" />
            <geometry>
                <mesh filename="package://ur_description/meshes/ur5e/visual/upperarm.dae" />
            </geometry>
        </visual>
        <collision>
            <origin rpy="1.5707963267948966 0 -1.5707963267948966" xyz="0 0 0.138" />
            <geometry>
                <mesh filename="package://ur_description/meshes/ur5e/collision/upperarm.stl" />
            </geometry>
        </collision>
        <inertial>
            <mass value="8.393" />
            <origin rpy="0 1.5707963267948966 0" xyz="-0.2125 0.0 0.138" />
            <inertia ixx="0.1338857818623325" ixy="0.0" ixz="0.0" iyy="0.1338857818623325" iyz="0.0" izz="0.0151074" />
        </inertial>
    </link>
    <link name="forearm_link">
        <visual>
            <origin rpy="1.5707963267948966 0 -1.5707963267948966" xyz="0 0 0.007" />
            <geometry>
                <mesh filename="package://ur_description/meshes/ur5e/visual/forearm.dae" />
            </geometry>
        </visual>
        <collision>
            <origin rpy="1.5707963267948966 0 -1.5707963267948966" xyz="0 0 0.007" />
            <geometry>
                <mesh filename="package://ur_description/meshes/ur5e/collision/forearm.stl" />
            </geometry>
        </collision>
        <inertial>
            <mass value="2.275" />
            <origin rpy="0 1.5707963267948966 0" xyz="-0.1961 0.0 0.007" />
            <inertia ixx="0.031209355099586295" ixy="0.0" ixz="0.0" iyy="0.031209355099586295" iyz="0.0" izz="0.004095" />
        </inertial>
    </link>
    <link name="wrist_1_link">
        <visual>
            <origin rpy="1.5707963267948966 0 0" xyz="0 0 -0.127" />
            <geometry>
                <mesh filename="package://ur_description/meshes/ur5e/visual/wrist1.dae" />
            </geometry>
        </visual>
        <collision>
            <origin rpy="1.5707963267948966 0 0" xyz="0 0 -0.127" />
            <geometry>
                <mesh filename="package://ur_description/meshes/ur5e/collision/wrist1.stl" />
            </geometry>
        </collision>
        <inertial>
            <mass value="1.219" />
            <origin rpy="0 0 0" xyz="0 0 0" />
            <inertia ixx="0.0025598989760400002" ixy="0.0" ixz="0.0" iyy="0.0025598989760400002" iyz="0.0" izz="0.0021942" />
        </inertial>
    </link>
    <link name="wrist_2_link">
        <visual>
            <origin rpy="0 0 0" xyz="0 0 -0.0997" />
            <geometry>
                <mesh filename="package://ur_description/meshes/ur5e/visual/wrist2.dae" />
            </geometry>
        </visual>
        <collision>
            <origin rpy="0 0 0" xyz="0 0 -0.0997" />
            <geometry>
                <mesh filename="package://ur_description/meshes/ur5e/collision/wrist2.stl" />
            </geometry>
        </collision>
        <inertial>
            <mass value="1.219" />
            <origin rpy="0 0 0" xyz="0 0 0" />
            <inertia ixx="0.0025598989760400002" ixy="0.0" ixz="0.0" iyy="0.0025598989760400002" iyz="0.0" izz="0.0021942" />
        </inertial>
    </link>
    <link name="wrist_3_link">
        <visual>
            <origin rpy="1.5707963267948966 0 0" xyz="0 0 -0.0989" />
            <geometry>
                <mesh filename="package://ur_description/meshes/ur5e/visual/wrist3.dae" />
            </geometry>
        </visual>
        <collision>
            <origin rpy="1.5707963267948966 0 0" xyz="0 0 -0.0989" />
            <geometry>
                <mesh filename="package://ur_description/meshes/ur5e/collision/wrist3.stl" />
            </geometry>
        </collision>
        <inertial>
            <mass value="0.1879" />
            <origin rpy="0 0 0" xyz="0.0 0.0 -0.0229" />
            <inertia ixx="9.890410052167731e-05" ixy="0.0" ixz="0.0" iyy="9.890410052167731e-05" iyz="0.0" izz="0.0001321171875" />
        </inertial>
    </link>
    <!-- base_joint fixes base_link to the environment -->
    <joint name="base_joint" type="fixed">
        <origin rpy="0 0 0" xyz="0 0 0" />
        <parent link="world" />
        <child link="base_link" />
    </joint>
    <!-- joints - main serial chain -->
    <!-- <joint name="${tf_prefix}base_link-base_link_inertia" type="fixed">
      <parent link="${tf_prefix}base_link" />
      <child link="${tf_prefix}base_link_inertia" /> -->
    <!-- 'base_link' is REP-103 aligned (so X+ forward), while the internal
           frames of the robot/controller have X+ pointing backwards.
           Use the joint between 'base_link' and 'base_link_inertia' (a dummy
           link/frame) to introduce the necessary rotation over Z (of pi rad).
      -->
    <!-- <origin xyz="0 0 0" rpy="0 0 ${pi}" />
    </joint> -->
    <joint name="shoulder_pan_joint" type="revolute">
        <parent link="base_link" />
        <!-- <parent link="${tf_prefix}base_link_inertia" /> -->
        <child link="shoulder_link" />
        <origin rpy="0 0 0" xyz="0 0 0.1625" />
        <axis xyz="0 0 1" />
        <limit effort="150.0" lower="-6.283185307179586" upper="6.283185307179586" velocity="3.141592653589793" />
        <dynamics damping="0" friction="0" />
    </joint>
    <joint name="shoulder_lift_joint" type="revolute">
        <parent link="shoulder_link" />
        <child link="upper_arm_link" />
        <origin rpy="1.570796327 0 0" xyz="0 0 0" />
        <axis xyz="0 0 1" />
        <limit effort="150.0" lower="-6.283185307179586" upper="6.283185307179586" velocity="3.141592653589793" />
        <dynamics damping="0" friction="0" />
    </joint>
    <joint name="elbow_joint" type="revolute">
        <parent link="upper_arm_link" />
        <child link="forearm_link" />
        <origin rpy="0 0 0" xyz="-0.425 0 0" />
        <axis xyz="0 0 1" />
        <limit effort="150.0" lower="-3.141592653589793" upper="3.141592653589793" velocity="3.141592653589793" />
        <dynamics damping="0" friction="0" />
    </joint>
    <joint name="wrist_1_joint" type="revolute">
        <parent link="forearm_link" />
        <child link="wrist_1_link" />
        <origin rpy="0 0 0" xyz="-0.3922 0 0.1333" />
        <axis xyz="0 0 1" />
        <limit effort="28.0" lower="-6.283185307179586" upper="6.283185307179586" velocity="3.141592653589793" />
        <dynamics damping="0" friction="0" />
    </joint>
    <joint name="wrist_2_joint" type="revolute">
        <parent link="wrist_1_link" />
        <child link="wrist_2_link" />
        <origin rpy="1.570796327 0 0" xyz="0 -0.0997 -2.044881182297852e-11" />
        <axis xyz="0 0 1" />
        <limit effort="28.0" lower="-6.283185307179586" upper="6.283185307179586" velocity="3.141592653589793" />
        <dynamics damping="0" friction="0" />
    </joint>
    <joint name="wrist_3_joint" type="revolute">
        <parent link="wrist_2_link" />
        <child link="wrist_3_link" />
        <origin rpy="1.570796326589793 3.141592653589793 3.141592653589793" xyz="0 0.0996 -2.042830148012698e-11" />
        <axis xyz="0 0 1" />
        <limit effort="28.0" lower="-6.283185307179586" upper="6.283185307179586" velocity="3.141592653589793" />
        <dynamics damping="0" friction="0" />
    </joint>
    <!-- <link name="${tf_prefix}ft_frame"/>
    <joint name="${tf_prefix}wrist_3_link-ft_frame" type="fixed">
      <parent link="${tf_prefix}wrist_3_link"/>
      <child link="${tf_prefix}ft_frame"/>
      <origin xyz="0 0 0" rpy="${pi} 0 0"/>
    </joint> -->
    <!-- ROS-Industrial 'base' frame - base_link to UR 'Base' Coordinates transform -->
    <!-- <link name="${tf_prefix}base"/>
    <joint name="${tf_prefix}base_link-base_fixed_joint" type="fixed"> -->
    <!-- Note the rotation over Z of pi radians - as base_link is REP-103
           aligned (i.e., has X+ forward, Y+ left and Z+ up), this is needed
           to correctly align 'base' with the 'Base' coordinate system of
           the UR controller.
      -->
    <!-- <origin xyz="0 0 0" rpy="0 0 ${pi}"/>
      <parent link="${tf_prefix}base_link"/>
      <child link="${tf_prefix}base"/>
    </joint> -->
    <!-- ROS-Industrial 'flange' frame - attachment point for EEF models -->
    <!-- <link name="${tf_prefix}flange" />
    <joint name="${tf_prefix}wrist_3-flange" type="fixed">
      <parent link="${tf_prefix}wrist_3_link" />
      <child link="${tf_prefix}flange" />
      <origin xyz="0 0 0" rpy="0 ${-pi/2.0} ${-pi/2.0}" />
    </joint> -->
    <!-- ROS-Industrial 'tool0' frame - all-zeros tool frame -->
    <!-- <link name="${tf_prefix}tool0"/>
    <joint name="${tf_prefix}flange-tool0" type="fixed"> -->
    <!-- default toolframe - X+ left, Y+ up, Z+ front -->
    <!-- <origin xyz="0 0 0" rpy="${pi/2.0} 0 ${pi/2.0}"/>
      <parent link="${tf_prefix}flange"/>
      <child link="${tf_prefix}tool0"/>
    </joint> -->
    <material name="aluminum">
        <color rgba="0.5 0.5 0.5 1" />
    </material>
    <material name="plastic">
        <color rgba="0.1 0.1 0.1 1" />
    </material>
    <!-- camera body, with origin at bottom screw mount -->
    <joint name="camera_joint" type="fixed">
        <origin rpy="0 -1.5707963268 0" xyz="0 0 0" />
        <parent link="wrist_3_link" />
        <child link="camera_bottom_screw_frame" />
    </joint>
    <link name="camera_bottom_screw_frame" />
    <joint name="camera_link_joint" type="fixed">
        <origin rpy="0 0 0" xyz="0.01085 0.009 0.021" />
        <parent link="camera_bottom_screw_frame" />
        <child link="camera_link" />
    </joint>
    <link name="camera_link">
        <visual>
            <!-- the mesh origin is at front plate in between the two infrared camera axes -->
            <origin rpy="1.5707963267948966 0 1.5707963267948966" xyz="0.0038 -0.009 0" />
            <geometry>
                <mesh filename="file:///home/iclab/work/src/camera_models/realsense2_description/meshes/d405.stl" scale="0.001 0.001 0.001" />
            </geometry>
            <material name="aluminum" />
        </visual>
        <collision>
            <origin rpy="0 0 0" xyz="-0.0078 -0.009 0" />
            <geometry>
                <box size="0.023 0.042 0.042" />
            </geometry>
        </collision>
        <inertial>
            <!-- The following are not reliable values, and should not be used for modeling -->
            <mass value="0.072" />
            <origin xyz="0 0 0" rpy="0 0 0" />
            <inertia ixx="0.003881243" ixy="0.0" ixz="0.0" iyy="0.000498940" iyz="0.0" izz="0.003879257" />
        </inertial>
    </link>
    <!-- camera depth joints and links -->
    <joint name="camera_depth_joint" type="fixed">
        <origin rpy="0 0 0" xyz="0 0 0" />
        <parent link="camera_link" />
        <child link="camera_depth_frame" />
    </joint>
    <link name="camera_depth_frame" />
    <joint name="camera_depth_optical_joint" type="fixed">
        <origin rpy="-1.5707963267948966 0 -1.5707963267948966" xyz="0 0 0" />
        <parent link="camera_depth_frame" />
        <child link="camera_depth_optical_frame" />
    </joint>
    <link name="camera_depth_optical_frame" />
    <!-- camera left IR joints and links -->
    <joint name="camera_infra1_joint" type="fixed">
        <origin rpy="0 0 0" xyz="0 0.0 0" />
        <parent link="camera_link" />
        <child link="camera_infra1_frame" />
    </joint>
    <link name="camera_infra1_frame" />
    <joint name="camera_infra1_optical_joint" type="fixed">
        <origin rpy="-1.5707963267948966 0 -1.5707963267948966" xyz="0 0 0" />
        <parent link="camera_infra1_frame" />
        <child link="camera_infra1_optical_frame" />
    </joint>
    <link name="camera_infra1_optical_frame" />
    <!-- camera right IR joints and links -->
    <joint name="camera_infra2_joint" type="fixed">
        <origin rpy="0 0 0" xyz="0 -0.018 0" />
        <parent link="camera_link" />
        <child link="camera_infra2_frame" />
    </joint>
    <link name="camera_infra2_frame" />
    <joint name="camera_infra2_optical_joint" type="fixed">
        <origin rpy="-1.5707963267948966 0 -1.5707963267948966" xyz="0 0 0" />
        <parent link="camera_infra2_frame" />
        <child link="camera_infra2_optical_frame" />
    </joint>
    <link name="camera_infra2_optical_frame" />
    <!-- camera color joints and links -->
    <joint name="camera_color_joint" type="fixed">
        <origin rpy="0 0 0" xyz="0 0.0 0" />
        <parent link="camera_link" />
        <child link="camera_color_frame" />
    </joint>
    <link name="camera_color_frame" />
    <joint name="camera_color_optical_joint" type="fixed">
        <origin rpy="-1.5707963267948966 0 -1.5707963267948966" xyz="0 0 0" />
        <parent link="camera_color_frame" />
        <child link="camera_color_optical_frame" />
    </joint>
    <link name="camera_color_optical_frame" />
    <transmission name="trans_shoulder_pan_joint">
        <type>transmission_interface/SimpleTransmission</type>
        <joint name="shoulder_pan_joint">
            <hardwareInterface>hardware_interface/EffortJointInterface</hardwareInterface>
        </joint>
        <actuator name="shoulder_pan_joint_motor">
            <hardwareInterface>hardware_interface/EffortJointInterface</hardwareInterface>
            <mechanicalReduction>1</mechanicalReduction>
        </actuator>
    </transmission>
    <transmission name="trans_shoulder_lift_joint">
        <type>transmission_interface/SimpleTransmission</type>
        <joint name="shoulder_lift_joint">
            <hardwareInterface>hardware_interface/EffortJointInterface</hardwareInterface>
        </joint>
        <actuator name="shoulder_lift_joint_motor">
            <hardwareInterface>hardware_interface/EffortJointInterface</hardwareInterface>
            <mechanicalReduction>1</mechanicalReduction>
        </actuator>
    </transmission>
    <transmission name="trans_elbow_joint">
        <type>transmission_interface/SimpleTransmission</type>
        <joint name="elbow_joint">
            <hardwareInterface>hardware_interface/EffortJointInterface</hardwareInterface>
        </joint>
        <actuator name="elbow_joint_motor">
            <hardwareInterface>hardware_interface/EffortJointInterface</hardwareInterface>
            <mechanicalReduction>1</mechanicalReduction>
        </actuator>
    </transmission>
    <transmission name="trans_wrist_1_joint">
        <type>transmission_interface/SimpleTransmission</type>
        <joint name="wrist_1_joint">
            <hardwareInterface>hardware_interface/EffortJointInterface</hardwareInterface>
        </joint>
        <actuator name="wrist_1_joint_motor">
            <hardwareInterface>hardware_interface/EffortJointInterface</hardwareInterface>
            <mechanicalReduction>1</mechanicalReduction>
        </actuator>
    </transmission>
    <transmission name="trans_wrist_2_joint">
        <type>transmission_interface/SimpleTransmission</type>
        <joint name="wrist_2_joint">
            <hardwareInterface>hardware_interface/EffortJointInterface</hardwareInterface>
        </joint>
        <actuator name="wrist_2_joint_motor">
            <hardwareInterface>hardware_interface/EffortJointInterface</hardwareInterface>
            <mechanicalReduction>1</mechanicalReduction>
        </actuator>
    </transmission>
    <transmission name="trans_wrist_3_joint">
        <type>transmission_interface/SimpleTransmission</type>
        <joint name="wrist_3_joint">
            <hardwareInterface>hardware_interface/EffortJointInterface</hardwareInterface>
        </joint>
        <actuator name="wrist_3_joint_motor">
            <hardwareInterface>hardware_interface/EffortJointInterface</hardwareInterface>
            <mechanicalReduction>1</mechanicalReduction>
        </actuator>
    </transmission>
    <gazebo>
        <plugin name="gazebo_ros_control">
            <robotNamespace>/</robotNamespace>
        </plugin>
    </gazebo>
</robot>

